Workbook

Sheet Guide
B2: MLB Hitter Monthly Tracker - 2026
B3: Emerson Jimenez | Emerson Performance (EP) | ejimenezperformance.github.io
B4: Source: Baseball Savant Statcast Search, pitch-level, 2026 regular season, all 30 teams (183,849 PA, 662 hitters). A traded hitter appears once per team, counting only the PAs he took for that team. Late-March games are grouped into "Mar-Apr".
B6: Tabs
B7: Player Card | C7: Pick a team, then a hitter (yellow cells): every metric by month + season, with trend charts.
B8: Team | C8: Pick a team: team offense by month next to the MLB season line.
B9: Trend Grid | C9: Pick a team: heat maps (hitters x months) for xwOBA, Barrel%, Chase% and Bat Speed. Hitters with 50+ PA for that team.
B10: Monthly Tracker | C10: Every team-hitter-month in MLB (use the filters). Each month vs. the hitter's season, with flags.
B11: Signal Weights | C11: League-wide test: how much of a monthly change carries into the next month. Read this before acting on a flag.
B12: Counts / Season Counts | C12: Hardcoded counting inputs from Statcast. Every other number in the workbook is a formula on these tabs.
B14: Key finding (all MLB hitters, 2026)
C15: Confirmed carry-over: Bat Speed. Bat speed: 44% of a month's change vs. the season line showed up again the next month (95% CI 0.31 to 0.57), CONFIRMED.
C16: wOBA, xwOBA, K%: no evidence a hot or cold month carries over beyond what its sample size already explains. The season line is the better guide; reacting fully to one month made next-month forecasts worse.
C17: Chase%, Barrel%: a small real carry-over, below the 0.20 bar set in advance. Watch, don't act alone.
C18: Bat speed vs. results: a slower-bat month did NOT come with a worse next-month xwOBA (+0.7 points per mph, 95% CI -7.6 to +8.4; NOT CONFIRMED). Use a ▼ Bat Speed flag for workload and health checks, not as a production forecast.
B20: Flag thresholds (edit the yellow cells)
B21: Min PA for a flag | C21: 40
B22: xwOBA change | C22: 0.04
B23: Chase% change | C23: 0.04
B24: Bat Speed change (mph) | C24: 1
B25: Min PA per month in Trend Grid | C25: 20
B26: Flags compare each month with the hitter's full season for that team (end-of-season view).
B28: Glossary
B29: wOBA / xwOBA | C29: Run value of outcomes / of contact quality (EV + LA, plus actual K/BB/HBP). Savant pitch-level weights; reached-on-error and fielder's choice count as outs.
B30: xwOBA - wOBA | C30: Positive = results trailed the contact (bad luck). Negative = results outran the contact.
B31: Barrel% / HardHit% | C31: Barrels (Statcast launch_speed_angle = 6) and 95+ mph batted balls, per batted-ball event.
B32: SweetSpot% | C32: Batted balls with launch angle 8-32 degrees, per batted-ball event.
B33: Chase% / Z-Swing% | C33: Swing rate on pitches outside the zone (zones 11-14) / inside the zone (zones 1-9).
B34: Whiff% / Z-Contact% | C34: Swinging strikes per swing (foul tips count as contact) / contact rate on in-zone swings.
B35: Bat Speed | C35: Average of competitive swings = the fastest 90% of the hitter's 2026 swings (bunts excluded), as on Savant.
B36: Fast-Swing% | C36: Competitive swings at 75+ mph.
B37: Run Value | C37: Sum of Statcast delta run expectancy over every pitch the hitter saw (runs above average).

Sheet Player Card
B2: Player Card
B3: Team: | C3: ATH | F3: <- choose a team, then a hitter from that team
B4: Hitter: | C4: Lawrence Butler | F4: =IF(COUNTIFS(Lists!$C$1:$C$739,$C$3,Lists!$D$1:$D$739,$C$4)=0,"Hitter not on this team - pick again","")
B6: Metric | C6: Mar-Apr | D6: May | E6: Jun | F6: Jul | G6: Aug | H6: Sep | I6: Season
B7: PA | C7: =IFERROR(SUMIFS(Counts!$P$2:$P$2903,Counts!$B$2:$B$2903,$C$3,Counts!$C$2:$C$2903,$C$4,Counts!$F$2:$F$2903,"Mar-Apr"),"") -> 105 | D7: =IFERROR(SUMIFS(Counts!$P$2:$P$2903,Counts!$B$2:$B$2903,$C$3,Counts!$C$2:$C$2903,$C$4,Counts!$F$2:$F$2903,"May"),"") -> 61 | E7: =IFERROR(SUMIFS(Counts!$P$2:$P$2903,Counts!$B$2:$B$2903,$C$3,Counts!$C$2:$C$2903,$C$4,Counts!$F$2:$F$2903,"Jun"),"") -> 71 | F7: =IFERROR(SUMIFS(Counts!$P$2:$P$2903,Counts!$B$2:$B$2903,$C$3,Counts!$C$2:$C$2903,$C$4,Counts!$F$2:$F$2903,"Jul"),"") -> 83 | G7: =IFERROR(SUMIFS(Counts!$P$2:$P$2903,Counts!$B$2:$B$2903,$C$3,Counts!$C$2:$C$2903,$C$4,Counts!$F$2:$F$2903,"Aug"),"") -> 116 | H7: =IFERROR(SUMIFS(Counts!$P$2:$P$2903,Counts!$B$2:$B$2903,$C$3,Counts!$C$2:$C$2903,$C$4,Counts!$F$2:$F$2903,"Sep"),"") -> 104 | I7: =IFERROR(SUMIFS(Counts!$P$2:$P$2903,Counts!$B$2:$B$2903,$C$3,Counts!$C$2:$C$2903,$C$4),"") -> 540
B8: AVG | C8: =IFERROR(SUMIFS(Counts!$R$2:$R$2903,Counts!$B$2:$B$2903,$C$3,Counts!$C$2:$C$2903,$C$4,Counts!$F$2:$F$2903,"Mar-Apr")/SUMIFS(Counts!$Q$2:$Q$2903,Counts!$B$2:$B$2903,$C$3,Counts!$C$2:$C$2903,$C$4,Counts!$F$2:$F$2903,"Mar-Apr"),"") -> 0.17894737 | D8: =IFERROR(SUMIFS(Counts!$R$2:$R$2903,Counts!$B$2:$B$2903,$C$3,Counts!$C$2:$C$2903,$C$4,Counts!$F$2:$F$2903,"May")/SUMIFS(Counts!$Q$2:$Q$2903,Counts!$B$2:$B$2903,$C$3,Counts!$C$2:$C$2903,$C$4,Counts!$F$2:$F$2903,"May"),"") -> 0.13461538 | E8: =IFERROR(SUMIFS(Counts!$R$2:$R$2903,Counts!$B$2:$B$2903,$C$3,Counts!$C$2:$C$2903,$C$4,Counts!$F$2:$F$2903,"Jun")/SUMIFS(Counts!$Q$2:$Q$2903,Counts!$B$2:$B$2903,$C$3,Counts!$C$2:$C$2903,$C$4,Counts!$F$2:$F$2903,"Jun"),"") -> 0.28125 | F8: =IFERROR(SUMIFS(Counts!$R$2:$R$2903,Counts!$B$2:$B$2903,$C$3,Counts!$C$2:$C$2903,$C$4,Counts!$F$2:$F$2903,"Jul")/SUMIFS(Counts!$Q$2:$Q$2903,Counts!$B$2:$B$2903,$C$3,Counts!$C$2:$C$2903,$C$4,Counts!$F$2:$F$2903,"Jul"),"") -> 0.2238806 | G8: =IFERROR(SUMIFS(Counts!$R$2:$R$2903,Counts!$B$2:$B$2903,$C$3,Counts!$C$2:$C$2903,$C$4,Counts!$F$2:$F$2903,"Aug")/SUMIFS(Counts!$Q$2:$Q$2903,Counts!$B$2:$B$2903,$C$3,Counts!$C$2:$C$2903,$C$4,Counts!$F$2:$F$2903,"Aug"),"") -> 0.2970297 | H8: =IFERROR(SUMIFS(Counts!$R$2:$R$2903,Counts!$B$2:$B$2903,$C$3,Counts!$C$2:$C$2903,$C$4,Counts!$F$2:$F$2903,"Sep")/SUMIFS(Counts!$Q$2:$Q$2903,Counts!$B$2:$B$2903,$C$3,Counts!$C$2:$C$2903,$C$4,Counts!$F$2:$F$2903,"Sep"),"") -> 0.26595745 | I8: =IFERROR(SUMIFS(Counts!$R$2:$R$2903,Counts!$B$2:$B$2903,$C$3,Counts!$C$2:$C$2903,$C$4)/SUMIFS(Counts!$Q$2:$Q$2903,Counts!$B$2:$B$2903,$C$3,Counts!$C$2:$C$2903,$C$4),"") -> 0.23678647
B9: OBP | C9: =IFERROR((SUMIFS(Counts!$R$2:$R$2903,Counts!$B$2:$B$2903,$C$3,Counts!$C$2:$C$2903,$C$4,Counts!$F$2:$F$2903,"Mar-Apr")+SUMIFS(Counts!$V$2:$V$2903,Counts!$B$2:$B$2903,$C$3,Counts!$C$2:$C$2903,$C$4,Counts!$F$2:$F$2903,"Mar-Apr")+SUMIFS(Counts!$W$2:$W$2903,Counts!$B$2:$B$2903,$C$3,Counts!$C$2:$C$2903,$C$4,Counts!$F$2:$F$2903,"Mar-Apr"))/(SUMIFS(Counts!$Q$2:$Q$2903,Counts!$B$2:$B$2903,$C$3,Counts!$C$2:$C$2903,$C$4,Counts!$F$2:$F$2903,"Mar-Apr")+SUMIFS(Counts!$V$2:$V$2903,Counts!$B$2:$B$2903,$C$3,Counts!$C$2:$C$2903,$C$4,Counts!$F$2:$F$2903,"Mar-Apr")+SUMIFS(Counts!$W$2:$W$2903,Counts!$B$2:$B$2903,$C$3,Counts!$C$2:$C$2903,$C$4,Counts!$F$2:$F$2903,"Mar-Apr")+SUMIFS(Counts!$X$2:$X$2903,Counts!$B$2:$B$2903,$C$3,Counts!$C$2:$C$2903,$C$4,Counts!$F$2:$F$2903,"Mar-Apr")),"") -> 0.25714286 | D9: =IFERROR((SUMIFS(Counts!$R$2:$R$2903,Counts!$B$2:$B$2903,$C$3,Counts!$C$2:$C$2903,$C$4,Counts!$F$2:$F$2903,"May")+SUMIFS(Counts!$V$2:$V$2903,Counts!$B$2:$B$2903,$C$3,Counts!$C$2:$C$2903,$C$4,Counts!$F$2:$F$2903,"May")+SUMIFS(Counts!$W$2:$W$2903,Counts!$B$2:$B$2903,$C$3,Counts!$C$2:$C$2903,$C$4,Counts!$F$2:$F$2903,"May"))/(SUMIFS(Counts!$Q$2:$Q$2903,Counts!$B$2:$B$2903,$C$3,Counts!$C$2:$C$2903,$C$4,Counts!$F$2:$F$2903,"May")+SUMIFS(Counts!$V$2:$V$2903,Counts!$B$2:$B$2903,$C$3,Counts!$C$2:$C$2903,$C$4,Counts!$F$2:$F$2903,"May")+SUMIFS(Counts!$W$2:$W$2903,Counts!$B$2:$B$2903,$C$3,Counts!$C$2:$C$2903,$C$4,Counts!$F$2:$F$2903,"May")+SUMIFS(Counts!$X$2:$X$2903,Counts!$B$2:$B$2903,$C$3,Counts!$C$2:$C$2903,$C$4,Counts!$F$2:$F$2903,"May")),"") -> 0.26229508 | E9: =IFERROR((SUMIFS(Counts!$R$2:$R$2903,Counts!$B$2:$B$2903,$C$3,Counts!$C$2:$C$2903,$C$4,Counts!$F$2:$F$2903,"Jun")+SUMIFS(Counts!$V$2:$V$2903,Counts!$B$2:$B$2903,$C$3,Counts!$C$2:$C$2903,$C$4,Counts!$F$2:$F$2903,"Jun")+SUMIFS(Counts!$W$2:$W$2903,Counts!$B$2:$B$2903,$C$3,Counts!$C$2:$C$2903,$C$4,Counts!$F$2:$F$2903,"Jun"))/(SUMIFS(Counts!$Q$2:$Q$2903,Counts!$B$2:$B$2903,$C$3,Counts!$C$2:$C$2903,$C$4,Counts!$F$2:$F$2903,"Jun")+SUMIFS(Counts!$V$2:$V$2903,Counts!$B$2:$B$2903,$C$3,Counts!$C$2:$C$2903,$C$4,Counts!$F$2:$F$2903,"Jun")+SUMIFS(Counts!$W$2:$W$2903,Counts!$B$2:$B$2903,$C$3,Counts!$C$2:$C$2903,$C$4,Counts!$F$2:$F$2903,"Jun")+SUMIFS(Counts!$X$2:$X$2903,Counts!$B$2:$B$2903,$C$3,Counts!$C$2:$C$2903,$C$4,Counts!$F$2:$F$2903,"Jun")),"") -> 0.35211268 | F9: =IFERROR((SUMIFS(Counts!$R$2:$R$2903,Counts!$B$2:$B$2903,$C$3,Counts!$C$2:$C$2903,$C$4,Counts!$F$2:$F$2903,"Jul")+SUMIFS(Counts!$V$2:$V$2903,Counts!$B$2:$B$2903,$C$3,Counts!$C$2:$C$2903,$C$4,Counts!$F$2:$F$2903,"Jul")+SUMIFS(Counts!$W$2:$W$2903,Counts!$B$2:$B$2903,$C$3,Counts!$C$2:$C$2903,$C$4,Counts!$F$2:$F$2903,"Jul"))/(SUMIFS(Counts!$Q$2:$Q$2903,Counts!$B$2:$B$2903,$C$3,Counts!$C$2:$C$2903,$C$4,Counts!$F$2:$F$2903,"Jul")+SUMIFS(Counts!$V$2:$V$2903,Counts!$B$2:$B$2903,$C$3,Counts!$C$2:$C$2903,$C$4,Counts!$F$2:$F$2903,"Jul")+SUMIFS(Counts!$W$2:$W$2903,Counts!$B$2:$B$2903,$C$3,Counts!$C$2:$C$2903,$C$4,Counts!$F$2:$F$2903,"Jul")+SUMIFS(Counts!$X$2:$X$2903,Counts!$B$2:$B$2903,$C$3,Counts!$C$2:$C$2903,$C$4,Counts!$F$2:$F$2903,"Jul")),"") -> 0.35365854 | G9: =IFERROR((SUMIFS(Counts!$R$2:$R$2903,Counts!$B$2:$B$2903,$C$3,Counts!$C$2:$C$2903,$C$4,Counts!$F$2:$F$2903,"Aug")+SUMIFS(Counts!$V$2:$V$2903,Counts!$B$2:$B$2903,$C$3,Counts!$C$2:$C$2903,$C$4,Counts!$F$2:$F$2903,"Aug")+SUMIFS(Counts!$W$2:$W$2903,Counts!$B$2:$B$2903,$C$3,Counts!$C$2:$C$2903,$C$4,Counts!$F$2:$F$2903,"Aug"))/(SUMIFS(Counts!$Q$2:$Q$2903,Counts!$B$2:$B$2903,$C$3,Counts!$C$2:$C$2903,$C$4,Counts!$F$2:$F$2903,"Aug")+SUMIFS(Counts!$V$2:$V$2903,Counts!$B$2:$B$2903,$C$3,Counts!$C$2:$C$2903,$C$4,Counts!$F$2:$F$2903,"Aug")+SUMIFS(Counts!$W$2:$W$2903,Counts!$B$2:$B$2903,$C$3,Counts!$C$2:$C$2903,$C$4,Counts!$F$2:$F$2903,"Aug")+SUMIFS(Counts!$X$2:$X$2903,Counts!$B$2:$B$2903,$C$3,Counts!$C$2:$C$2903,$C$4,Counts!$F$2:$F$2903,"Aug")),"") -> 0.38793103 | H9: =IFERROR((SUMIFS(Counts!$R$2:$R$2903,Counts!$B$2:$B$2903,$C$3,Counts!$C$2:$C$2903,$C$4,Counts!$F$2:$F$2903,"Sep")+SUMIFS(Counts!$V$2:$V$2903,Counts!$B$2:$B$2903,$C$3,Counts!$C$2:$C$2903,$C$4,Counts!$F$2:$F$2903,"Sep")+SUMIFS(Counts!$W$2:$W$2903,Counts!$B$2:$B$2903,$C$3,Counts!$C$2:$C$2903,$C$4,Counts!$F$2:$F$2903,"Sep"))/(SUMIFS(Counts!$Q$2:$Q$2903,Counts!$B$2:$B$2903,$C$3,Counts!$C$2:$C$2903,$C$4,Counts!$F$2:$F$2903,"Sep")+SUMIFS(Counts!$V$2:$V$2903,Counts!$B$2:$B$2903,$C$3,Counts!$C$2:$C$2903,$C$4,Counts!$F$2:$F$2903,"Sep")+SUMIFS(Counts!$W$2:$W$2903,Counts!$B$2:$B$2903,$C$3,Counts!$C$2:$C$2903,$C$4,Counts!$F$2:$F$2903,"Sep")+SUMIFS(Counts!$X$2:$X$2903,Counts!$B$2:$B$2903,$C$3,Counts!$C$2:$C$2903,$C$4,Counts!$F$2:$F$2903,"Sep")),"") -> 0.32038835 | I9: =IFERROR((SUMIFS(Counts!$R$2:$R$2903,Counts!$B$2:$B$2903,$C$3,Counts!$C$2:$C$2903,$C$4)+SUMIFS(Counts!$V$2:$V$2903,Counts!$B$2:$B$2903,$C$3,Counts!$C$2:$C$2903,$C$4)+SUMIFS(Counts!$W$2:$W$2903,Counts!$B$2:$B$2903,$C$3,Counts!$C$2:$C$2903,$C$4))/(SUMIFS(Counts!$Q$2:$Q$2903,Counts!$B$2:$B$2903,$C$3,Counts!$C$2:$C$2903,$C$4)+SUMIFS(Counts!$V$2:$V$2903,Counts!$B$2:$B$2903,$C$3,Counts!$C$2:$C$2903,$C$4)+SUMIFS(Counts!$W$2:$W$2903,Counts!$B$2:$B$2903,$C$3,Counts!$C$2:$C$2903,$C$4)+SUMIFS(Counts!$X$2:$X$2903,Counts!$B$2:$B$2903,$C$3,Counts!$C$2:$C$2903,$C$4)),"") -> 0.32527881
B10: SLG | C10: =IFERROR((SUMIFS(Counts!$R$2:$R$2903,Counts!$B$2:$B$2903,$C$3,Counts!$C$2:$C$2903,$C$4,Counts!$F$2:$F$2903,"Mar-Apr")+SUMIFS(Counts!$S$2:$S$2903,Counts!$B$2:$B$2903,$C$3,Counts!$C$2:$C$2903,$C$4,Counts!$F$2:$F$2903,"Mar-Apr")+2*SUMIFS(Counts!$T$2:$T$2903,Counts!$B$2:$B$2903,$C$3,Counts!$C$2:$C$2903,$C$4,Counts!$F$2:$F$2903,"Mar-Apr")+3*SUMIFS(Counts!$U$2:$U$2903,Counts!$B$2:$B$2903,$C$3,Counts!$C$2:$C$2903,$C$4,Counts!$F$2:$F$2903,"Mar-Apr"))/SUMIFS(Counts!$Q$2:$Q$2903,Counts!$B$2:$B$2903,$C$3,Counts!$C$2:$C$2903,$C$4,Counts!$F$2:$F$2903,"Mar-Apr"),"") -> 0.29473684 | D10: =IFERROR((SUMIFS(Counts!$R$2:$R$2903,Counts!$B$2:$B$2903,$C$3,Counts!$C$2:$C$2903,$C$4,Counts!$F$2:$F$2903,"May")+SUMIFS(Counts!$S$2:$S$2903,Counts!$B$2:$B$2903,$C$3,Counts!$C$2:$C$2903,$C$4,Counts!$F$2:$F$2903,"May")+2*SUMIFS(Counts!$T$2:$T$2903,Counts!$B$2:$B$2903,$C$3,Counts!$C$2:$C$2903,$C$4,Counts!$F$2:$F$2903,"May")+3*SUMIFS(Counts!$U$2:$U$2903,Counts!$B$2:$B$2903,$C$3,Counts!$C$2:$C$2903,$C$4,Counts!$F$2:$F$2903,"May"))/SUMIFS(Counts!$Q$2:$Q$2903,Counts!$B$2:$B$2903,$C$3,Counts!$C$2:$C$2903,$C$4,Counts!$F$2:$F$2903,"May"),"") -> 0.15384615 | E10: =IFERROR((SUMIFS(Counts!$R$2:$R$2903,Counts!$B$2:$B$2903,$C$3,Counts!$C$2:$C$2903,$C$4,Counts!$F$2:$F$2903,"Jun")+SUMIFS(Counts!$S$2:$S$2903,Counts!$B$2:$B$2903,$C$3,Counts!$C$2:$C$2903,$C$4,Counts!$F$2:$F$2903,"Jun")+2*SUMIFS(Counts!$T$2:$T$2903,Counts!$B$2:$B$2903,$C$3,Counts!$C$2:$C$2903,$C$4,Counts!$F$2:$F$2903,"Jun")+3*SUMIFS(Counts!$U$2:$U$2903,Counts!$B$2:$B$2903,$C$3,Counts!$C$2:$C$2903,$C$4,Counts!$F$2:$F$2903,"Jun"))/SUMIFS(Counts!$Q$2:$Q$2903,Counts!$B$2:$B$2903,$C$3,Counts!$C$2:$C$2903,$C$4,Counts!$F$2:$F$2903,"Jun"),"") -> 0.4375 | F10: =IFERROR((SUMIFS(Counts!$R$2:$R$2903,Counts!$B$2:$B$2903,$C$3,Counts!$C$2:$C$2903,$C$4,Counts!$F$2:$F$2903,"Jul")+SUMIFS(Counts!$S$2:$S$2903,Counts!$B$2:$B$2903,$C$3,Counts!$C$2:$C$2903,$C$4,Counts!$F$2:$F$2903,"Jul")+2*SUMIFS(Counts!$T$2:$T$2903,Counts!$B$2:$B$2903,$C$3,Counts!$C$2:$C$2903,$C$4,Counts!$F$2:$F$2903,"Jul")+3*SUMIFS(Counts!$U$2:$U$2903,Counts!$B$2:$B$2903,$C$3,Counts!$C$2:$C$2903,$C$4,Counts!$F$2:$F$2903,"Jul"))/SUMIFS(Counts!$Q$2:$Q$2903,Counts!$B$2:$B$2903,$C$3,Counts!$C$2:$C$2903,$C$4,Counts!$F$2:$F$2903,"Jul"),"") -> 0.3880597 | G10: =IFERROR((SUMIFS(Counts!$R$2:$R$2903,Counts!$B$2:$B$2903,$C$3,Counts!$C$2:$C$2903,$C$4,Counts!$F$2:$F$2903,"Aug")+SUMIFS(Counts!$S$2:$S$2903,Counts!$B$2:$B$2903,$C$3,Counts!$C$2:$C$2903,$C$4,Counts!$F$2:$F$2903,"Aug")+2*SUMIFS(Counts!$T$2:$T$2903,Counts!$B$2:$B$2903,$C$3,Counts!$C$2:$C$2903,$C$4,Counts!$F$2:$F$2903,"Aug")+3*SUMIFS(Counts!$U$2:$U$2903,Counts!$B$2:$B$2903,$C$3,Counts!$C$2:$C$2903,$C$4,Counts!$F$2:$F$2903,"Aug"))/SUMIFS(Counts!$Q$2:$Q$2903,Counts!$B$2:$B$2903,$C$3,Counts!$C$2:$C$2903,$C$4,Counts!$F$2:$F$2903,"Aug"),"") -> 0.5049505 | H10: =IFERROR((SUMIFS(Counts!$R$2:$R$2903,Counts!$B$2:$B$2903,$C$3,Counts!$C$2:$C$2903,$C$4,Counts!$F$2:$F$2903,"Sep")+SUMIFS(Counts!$S$2:$S$2903,Counts!$B$2:$B$2903,$C$3,Counts!$C$2:$C$2903,$C$4,Counts!$F$2:$F$2903,"Sep")+2*SUMIFS(Counts!$T$2:$T$2903,Counts!$B$2:$B$2903,$C$3,Counts!$C$2:$C$2903,$C$4,Counts!$F$2:$F$2903,"Sep")+3*SUMIFS(Counts!$U$2:$U$2903,Counts!$B$2:$B$2903,$C$3,Counts!$C$2:$C$2903,$C$4,Counts!$F$2:$F$2903,"Sep"))/SUMIFS(Counts!$Q$2:$Q$2903,Counts!$B$2:$B$2903,$C$3,Counts!$C$2:$C$2903,$C$4,Counts!$F$2:$F$2903,"Sep"),"") -> 0.4787234 | I10: =IFERROR((SUMIFS(Counts!$R$2:$R$2903,Counts!$B$2:$B$2903,$C$3,Counts!$C$2:$C$2903,$C$4)+SUMIFS(Counts!$S$2:$S$2903,Counts!$B$2:$B$2903,$C$3,Counts!$C$2:$C$2903,$C$4)+2*SUMIFS(Counts!$T$2:$T$2903,Counts!$B$2:$B$2903,$C$3,Counts!$C$2:$C$2903,$C$4)+3*SUMIFS(Counts!$U$2:$U$2903,Counts!$B$2:$B$2903,$C$3,Counts!$C$2:$C$2903,$C$4))/SUMIFS(Counts!$Q$2:$Q$2903,Counts!$B$2:$B$2903,$C$3,Counts!$C$2:$C$2903,$C$4),"") -> 0.39323467
B11: HR | C11: =IFERROR(SUMIFS(Counts!$U$2:$U$2903,Counts!$B$2:$B$2903,$C$3,Counts!$C$2:$C$2903,$C$4,Counts!$F$2:$F$2903,"Mar-Apr"),"") -> 3 | D11: =IFERROR(SUMIFS(Counts!$U$2:$U$2903,Counts!$B$2:$B$2903,$C$3,Counts!$C$2:$C$2903,$C$4,Counts!$F$2:$F$2903,"May"),"") -> 0 | E11: =IFERROR(SUMIFS(Counts!$U$2:$U$2903,Counts!$B$2:$B$2903,$C$3,Counts!$C$2:$C$2903,$C$4,Counts!$F$2:$F$2903,"Jun"),"") -> 2 | F11: =IFERROR(SUMIFS(Counts!$U$2:$U$2903,Counts!$B$2:$B$2903,$C$3,Counts!$C$2:$C$2903,$C$4,Counts!$F$2:$F$2903,"Jul"),"") -> 1 | G11: =IFERROR(SUMIFS(Counts!$U$2:$U$2903,Counts!$B$2:$B$2903,$C$3,Counts!$C$2:$C$2903,$C$4,Counts!$F$2:$F$2903,"Aug"),"") -> 6 | H11: =IFERROR(SUMIFS(Counts!$U$2:$U$2903,Counts!$B$2:$B$2903,$C$3,Counts!$C$2:$C$2903,$C$4,Counts!$F$2:$F$2903,"Sep"),"") -> 5 | I11: =IFERROR(SUMIFS(Counts!$U$2:$U$2903,Counts!$B$2:$B$2903,$C$3,Counts!$C$2:$C$2903,$C$4),"") -> 17
B12: wOBA | C12: =IFERROR(SUMIFS(Counts!$Z$2:$Z$2903,Counts!$B$2:$B$2903,$C$3,Counts!$C$2:$C$2903,$C$4,Counts!$F$2:$F$2903,"Mar-Apr")/SUMIFS(Counts!$AA$2:$AA$2903,Counts!$B$2:$B$2903,$C$3,Counts!$C$2:$C$2903,$C$4,Counts!$F$2:$F$2903,"Mar-Apr"),"") -> 0.24615385 | D12: =IFERROR(SUMIFS(Counts!$Z$2:$Z$2903,Counts!$B$2:$B$2903,$C$3,Counts!$C$2:$C$2903,$C$4,Counts!$F$2:$F$2903,"May")/SUMIFS(Counts!$AA$2:$AA$2903,Counts!$B$2:$B$2903,$C$3,Counts!$C$2:$C$2903,$C$4,Counts!$F$2:$F$2903,"May"),"") -> 0.21949153 | E12: =IFERROR(SUMIFS(Counts!$Z$2:$Z$2903,Counts!$B$2:$B$2903,$C$3,Counts!$C$2:$C$2903,$C$4,Counts!$F$2:$F$2903,"Jun")/SUMIFS(Counts!$AA$2:$AA$2903,Counts!$B$2:$B$2903,$C$3,Counts!$C$2:$C$2903,$C$4,Counts!$F$2:$F$2903,"Jun"),"") -> 0.35285714 | F12: =IFERROR(SUMIFS(Counts!$Z$2:$Z$2903,Counts!$B$2:$B$2903,$C$3,Counts!$C$2:$C$2903,$C$4,Counts!$F$2:$F$2903,"Jul")/SUMIFS(Counts!$AA$2:$AA$2903,Counts!$B$2:$B$2903,$C$3,Counts!$C$2:$C$2903,$C$4,Counts!$F$2:$F$2903,"Jul"),"") -> 0.33170732 | G12: =IFERROR(SUMIFS(Counts!$Z$2:$Z$2903,Counts!$B$2:$B$2903,$C$3,Counts!$C$2:$C$2903,$C$4,Counts!$F$2:$F$2903,"Aug")/SUMIFS(Counts!$AA$2:$AA$2903,Counts!$B$2:$B$2903,$C$3,Counts!$C$2:$C$2903,$C$4,Counts!$F$2:$F$2903,"Aug"),"") -> 0.38922414 | H12: =IFERROR(SUMIFS(Counts!$Z$2:$Z$2903,Counts!$B$2:$B$2903,$C$3,Counts!$C$2:$C$2903,$C$4,Counts!$F$2:$F$2903,"Sep")/SUMIFS(Counts!$AA$2:$AA$2903,Counts!$B$2:$B$2903,$C$3,Counts!$C$2:$C$2903,$C$4,Counts!$F$2:$F$2903,"Sep"),"") -> 0.34320388 | I12: =IFERROR(SUMIFS(Counts!$Z$2:$Z$2903,Counts!$B$2:$B$2903,$C$3,Counts!$C$2:$C$2903,$C$4)/SUMIFS(Counts!$AA$2:$AA$2903,Counts!$B$2:$B$2903,$C$3,Counts!$C$2:$C$2903,$C$4),"") -> 0.32013109
B13: xwOBA | C13: =IFERROR(SUMIFS(Counts!$AB$2:$AB$2903,Counts!$B$2:$B$2903,$C$3,Counts!$C$2:$C$2903,$C$4,Counts!$F$2:$F$2903,"Mar-Apr")/SUMIFS(Counts!$AA$2:$AA$2903,Counts!$B$2:$B$2903,$C$3,Counts!$C$2:$C$2903,$C$4,Counts!$F$2:$F$2903,"Mar-Apr"),"") -> 0.30085577 | D13: =IFERROR(SUMIFS(Counts!$AB$2:$AB$2903,Counts!$B$2:$B$2903,$C$3,Counts!$C$2:$C$2903,$C$4,Counts!$F$2:$F$2903,"May")/SUMIFS(Counts!$AA$2:$AA$2903,Counts!$B$2:$B$2903,$C$3,Counts!$C$2:$C$2903,$C$4,Counts!$F$2:$F$2903,"May"),"") -> 0.28949153 | E13: =IFERROR(SUMIFS(Counts!$AB$2:$AB$2903,Counts!$B$2:$B$2903,$C$3,Counts!$C$2:$C$2903,$C$4,Counts!$F$2:$F$2903,"Jun")/SUMIFS(Counts!$AA$2:$AA$2903,Counts!$B$2:$B$2903,$C$3,Counts!$C$2:$C$2903,$C$4,Counts!$F$2:$F$2903,"Jun"),"") -> 0.33995714 | F13: =IFERROR(SUMIFS(Counts!$AB$2:$AB$2903,Counts!$B$2:$B$2903,$C$3,Counts!$C$2:$C$2903,$C$4,Counts!$F$2:$F$2903,"Jul")/SUMIFS(Counts!$AA$2:$AA$2903,Counts!$B$2:$B$2903,$C$3,Counts!$C$2:$C$2903,$C$4,Counts!$F$2:$F$2903,"Jul"),"") -> 0.30909756 | G13: =IFERROR(SUMIFS(Counts!$AB$2:$AB$2903,Counts!$B$2:$B$2903,$C$3,Counts!$C$2:$C$2903,$C$4,Counts!$F$2:$F$2903,"Aug")/SUMIFS(Counts!$AA$2:$AA$2903,Counts!$B$2:$B$2903,$C$3,Counts!$C$2:$C$2903,$C$4,Counts!$F$2:$F$2903,"Aug"),"") -> 0.34437069 | H13: =IFERROR(SUMIFS(Counts!$AB$2:$AB$2903,Counts!$B$2:$B$2903,$C$3,Counts!$C$2:$C$2903,$C$4,Counts!$F$2:$F$2903,"Sep")/SUMIFS(Counts!$AA$2:$AA$2903,Counts!$B$2:$B$2903,$C$3,Counts!$C$2:$C$2903,$C$4,Counts!$F$2:$F$2903,"Sep"),"") -> 0.35547573 | I13: =IFERROR(SUMIFS(Counts!$AB$2:$AB$2903,Counts!$B$2:$B$2903,$C$3,Counts!$C$2:$C$2903,$C$4)/SUMIFS(Counts!$AA$2:$AA$2903,Counts!$B$2:$B$2903,$C$3,Counts!$C$2:$C$2903,$C$4),"") -> 0.3259794
B14: xwOBA - wOBA | C14: =IFERROR((SUMIFS(Counts!$AB$2:$AB$2903,Counts!$B$2:$B$2903,$C$3,Counts!$C$2:$C$2903,$C$4,Counts!$F$2:$F$2903,"Mar-Apr")-SUMIFS(Counts!$Z$2:$Z$2903,Counts!$B$2:$B$2903,$C$3,Counts!$C$2:$C$2903,$C$4,Counts!$F$2:$F$2903,"Mar-Apr"))/SUMIFS(Counts!$AA$2:$AA$2903,Counts!$B$2:$B$2903,$C$3,Counts!$C$2:$C$2903,$C$4,Counts!$F$2:$F$2903,"Mar-Apr"),"") -> 0.054701923 | D14: =IFERROR((SUMIFS(Counts!$AB$2:$AB$2903,Counts!$B$2:$B$2903,$C$3,Counts!$C$2:$C$2903,$C$4,Counts!$F$2:$F$2903,"May")-SUMIFS(Counts!$Z$2:$Z$2903,Counts!$B$2:$B$2903,$C$3,Counts!$C$2:$C$2903,$C$4,Counts!$F$2:$F$2903,"May"))/SUMIFS(Counts!$AA$2:$AA$2903,Counts!$B$2:$B$2903,$C$3,Counts!$C$2:$C$2903,$C$4,Counts!$F$2:$F$2903,"May"),"") -> 0.07 | E14: =IFERROR((SUMIFS(Counts!$AB$2:$AB$2903,Counts!$B$2:$B$2903,$C$3,Counts!$C$2:$C$2903,$C$4,Counts!$F$2:$F$2903,"Jun")-SUMIFS(Counts!$Z$2:$Z$2903,Counts!$B$2:$B$2903,$C$3,Counts!$C$2:$C$2903,$C$4,Counts!$F$2:$F$2903,"Jun"))/SUMIFS(Counts!$AA$2:$AA$2903,Counts!$B$2:$B$2903,$C$3,Counts!$C$2:$C$2903,$C$4,Counts!$F$2:$F$2903,"Jun"),"") -> -0.0129 | F14: =IFERROR((SUMIFS(Counts!$AB$2:$AB$2903,Counts!$B$2:$B$2903,$C$3,Counts!$C$2:$C$2903,$C$4,Counts!$F$2:$F$2903,"Jul")-SUMIFS(Counts!$Z$2:$Z$2903,Counts!$B$2:$B$2903,$C$3,Counts!$C$2:$C$2903,$C$4,Counts!$F$2:$F$2903,"Jul"))/SUMIFS(Counts!$AA$2:$AA$2903,Counts!$B$2:$B$2903,$C$3,Counts!$C$2:$C$2903,$C$4,Counts!$F$2:$F$2903,"Jul"),"") -> -0.022609756 | G14: =IFERROR((SUMIFS(Counts!$AB$2:$AB$2903,Counts!$B$2:$B$2903,$C$3,Counts!$C$2:$C$2903,$C$4,Counts!$F$2:$F$2903,"Aug")-SUMIFS(Counts!$Z$2:$Z$2903,Counts!$B$2:$B$2903,$C$3,Counts!$C$2:$C$2903,$C$4,Counts!$F$2:$F$2903,"Aug"))/SUMIFS(Counts!$AA$2:$AA$2903,Counts!$B$2:$B$2903,$C$3,Counts!$C$2:$C$2903,$C$4,Counts!$F$2:$F$2903,"Aug"),"") -> -0.044853448 | H14: =IFERROR((SUMIFS(Counts!$AB$2:$AB$2903,Counts!$B$2:$B$2903,$C$3,Counts!$C$2:$C$2903,$C$4,Counts!$F$2:$F$2903,"Sep")-SUMIFS(Counts!$Z$2:$Z$2903,Counts!$B$2:$B$2903,$C$3,Counts!$C$2:$C$2903,$C$4,Counts!$F$2:$F$2903,"Sep"))/SUMIFS(Counts!$AA$2:$AA$2903,Counts!$B$2:$B$2903,$C$3,Counts!$C$2:$C$2903,$C$4,Counts!$F$2:$F$2903,"Sep"),"") -> 0.012271845 | I14: =IFERROR((SUMIFS(Counts!$AB$2:$AB$2903,Counts!$B$2:$B$2903,$C$3,Counts!$C$2:$C$2903,$C$4)-SUMIFS(Counts!$Z$2:$Z$2903,Counts!$B$2:$B$2903,$C$3,Counts!$C$2:$C$2903,$C$4))/SUMIFS(Counts!$AA$2:$AA$2903,Counts!$B$2:$B$2903,$C$3,Counts!$C$2:$C$2903,$C$4),"") -> 0.0058483146
B15: K% | C15: =IFERROR(SUMIFS(Counts!$Y$2:$Y$2903,Counts!$B$2:$B$2903,$C$3,Counts!$C$2:$C$2903,$C$4,Counts!$F$2:$F$2903,"Mar-Apr")/SUMIFS(Counts!$P$2:$P$2903,Counts!$B$2:$B$2903,$C$3,Counts!$C$2:$C$2903,$C$4,Counts!$F$2:$F$2903,"Mar-Apr"),"") -> 0.27619048 | D15: =IFERROR(SUMIFS(Counts!$Y$2:$Y$2903,Counts!$B$2:$B$2903,$C$3,Counts!$C$2:$C$2903,$C$4,Counts!$F$2:$F$2903,"May")/SUMIFS(Counts!$P$2:$P$2903,Counts!$B$2:$B$2903,$C$3,Counts!$C$2:$C$2903,$C$4,Counts!$F$2:$F$2903,"May"),"") -> 0.24590164 | E15: =IFERROR(SUMIFS(Counts!$Y$2:$Y$2903,Counts!$B$2:$B$2903,$C$3,Counts!$C$2:$C$2903,$C$4,Counts!$F$2:$F$2903,"Jun")/SUMIFS(Counts!$P$2:$P$2903,Counts!$B$2:$B$2903,$C$3,Counts!$C$2:$C$2903,$C$4,Counts!$F$2:$F$2903,"Jun"),"") -> 0.29577465 | F15: =IFERROR(SUMIFS(Counts!$Y$2:$Y$2903,Counts!$B$2:$B$2903,$C$3,Counts!$C$2:$C$2903,$C$4,Counts!$F$2:$F$2903,"Jul")/SUMIFS(Counts!$P$2:$P$2903,Counts!$B$2:$B$2903,$C$3,Counts!$C$2:$C$2903,$C$4,Counts!$F$2:$F$2903,"Jul"),"") -> 0.24096386 | G15: =IFERROR(SUMIFS(Counts!$Y$2:$Y$2903,Counts!$B$2:$B$2903,$C$3,Counts!$C$2:$C$2903,$C$4,Counts!$F$2:$F$2903,"Aug")/SUMIFS(Counts!$P$2:$P$2903,Counts!$B$2:$B$2903,$C$3,Counts!$C$2:$C$2903,$C$4,Counts!$F$2:$F$2903,"Aug"),"") -> 0.24137931 | H15: =IFERROR(SUMIFS(Counts!$Y$2:$Y$2903,Counts!$B$2:$B$2903,$C$3,Counts!$C$2:$C$2903,$C$4,Counts!$F$2:$F$2903,"Sep")/SUMIFS(Counts!$P$2:$P$2903,Counts!$B$2:$B$2903,$C$3,Counts!$C$2:$C$2903,$C$4,Counts!$F$2:$F$2903,"Sep"),"") -> 0.25 | I15: =IFERROR(SUMIFS(Counts!$Y$2:$Y$2903,Counts!$B$2:$B$2903,$C$3,Counts!$C$2:$C$2903,$C$4)/SUMIFS(Counts!$P$2:$P$2903,Counts!$B$2:$B$2903,$C$3,Counts!$C$2:$C$2903,$C$4),"") -> 0.25740741
B16: BB% | C16: =IFERROR(SUMIFS(Counts!$V$2:$V$2903,Counts!$B$2:$B$2903,$C$3,Counts!$C$2:$C$2903,$C$4,Counts!$F$2:$F$2903,"Mar-Apr")/SUMIFS(Counts!$P$2:$P$2903,Counts!$B$2:$B$2903,$C$3,Counts!$C$2:$C$2903,$C$4,Counts!$F$2:$F$2903,"Mar-Apr"),"") -> 0.095238095 | D16: =IFERROR(SUMIFS(Counts!$V$2:$V$2903,Counts!$B$2:$B$2903,$C$3,Counts!$C$2:$C$2903,$C$4,Counts!$F$2:$F$2903,"May")/SUMIFS(Counts!$P$2:$P$2903,Counts!$B$2:$B$2903,$C$3,Counts!$C$2:$C$2903,$C$4,Counts!$F$2:$F$2903,"May"),"") -> 0.14754098 | E16: =IFERROR(SUMIFS(Counts!$V$2:$V$2903,Counts!$B$2:$B$2903,$C$3,Counts!$C$2:$C$2903,$C$4,Counts!$F$2:$F$2903,"Jun")/SUMIFS(Counts!$P$2:$P$2903,Counts!$B$2:$B$2903,$C$3,Counts!$C$2:$C$2903,$C$4,Counts!$F$2:$F$2903,"Jun"),"") -> 0.098591549 | F16: =IFERROR(SUMIFS(Counts!$V$2:$V$2903,Counts!$B$2:$B$2903,$C$3,Counts!$C$2:$C$2903,$C$4,Counts!$F$2:$F$2903,"Jul")/SUMIFS(Counts!$P$2:$P$2903,Counts!$B$2:$B$2903,$C$3,Counts!$C$2:$C$2903,$C$4,Counts!$F$2:$F$2903,"Jul"),"") -> 0.15662651 | G16: =IFERROR(SUMIFS(Counts!$V$2:$V$2903,Counts!$B$2:$B$2903,$C$3,Counts!$C$2:$C$2903,$C$4,Counts!$F$2:$F$2903,"Aug")/SUMIFS(Counts!$P$2:$P$2903,Counts!$B$2:$B$2903,$C$3,Counts!$C$2:$C$2903,$C$4,Counts!$F$2:$F$2903,"Aug"),"") -> 0.12931034 | H16: =IFERROR(SUMIFS(Counts!$V$2:$V$2903,Counts!$B$2:$B$2903,$C$3,Counts!$C$2:$C$2903,$C$4,Counts!$F$2:$F$2903,"Sep")/SUMIFS(Counts!$P$2:$P$2903,Counts!$B$2:$B$2903,$C$3,Counts!$C$2:$C$2903,$C$4,Counts!$F$2:$F$2903,"Sep"),"") -> 0.067307692 | I16: =IFERROR(SUMIFS(Counts!$V$2:$V$2903,Counts!$B$2:$B$2903,$C$3,Counts!$C$2:$C$2903,$C$4)/SUMIFS(Counts!$P$2:$P$2903,Counts!$B$2:$B$2903,$C$3,Counts!$C$2:$C$2903,$C$4),"") -> 0.11296296
B17: Barrel% | C17: =IFERROR(SUMIFS(Counts!$AD$2:$AD$2903,Counts!$B$2:$B$2903,$C$3,Counts!$C$2:$C$2903,$C$4,Counts!$F$2:$F$2903,"Mar-Apr")/SUMIFS(Counts!$AC$2:$AC$2903,Counts!$B$2:$B$2903,$C$3,Counts!$C$2:$C$2903,$C$4,Counts!$F$2:$F$2903,"Mar-Apr"),"") -> 0.075757576 | D17: =IFERROR(SUMIFS(Counts!$AD$2:$AD$2903,Counts!$B$2:$B$2903,$C$3,Counts!$C$2:$C$2903,$C$4,Counts!$F$2:$F$2903,"May")/SUMIFS(Counts!$AC$2:$AC$2903,Counts!$B$2:$B$2903,$C$3,Counts!$C$2:$C$2903,$C$4,Counts!$F$2:$F$2903,"May"),"") -> 0.027027027 | E17: =IFERROR(SUMIFS(Counts!$AD$2:$AD$2903,Counts!$B$2:$B$2903,$C$3,Counts!$C$2:$C$2903,$C$4,Counts!$F$2:$F$2903,"Jun")/SUMIFS(Counts!$AC$2:$AC$2903,Counts!$B$2:$B$2903,$C$3,Counts!$C$2:$C$2903,$C$4,Counts!$F$2:$F$2903,"Jun"),"") -> 0.093023256 | F17: =IFERROR(SUMIFS(Counts!$AD$2:$AD$2903,Counts!$B$2:$B$2903,$C$3,Counts!$C$2:$C$2903,$C$4,Counts!$F$2:$F$2903,"Jul")/SUMIFS(Counts!$AC$2:$AC$2903,Counts!$B$2:$B$2903,$C$3,Counts!$C$2:$C$2903,$C$4,Counts!$F$2:$F$2903,"Jul"),"") -> 0.081632653 | G17: =IFERROR(SUMIFS(Counts!$AD$2:$AD$2903,Counts!$B$2:$B$2903,$C$3,Counts!$C$2:$C$2903,$C$4,Counts!$F$2:$F$2903,"Aug")/SUMIFS(Counts!$AC$2:$AC$2903,Counts!$B$2:$B$2903,$C$3,Counts!$C$2:$C$2903,$C$4,Counts!$F$2:$F$2903,"Aug"),"") -> 0.082191781 | H17: =IFERROR(SUMIFS(Counts!$AD$2:$AD$2903,Counts!$B$2:$B$2903,$C$3,Counts!$C$2:$C$2903,$C$4,Counts!$F$2:$F$2903,"Sep")/SUMIFS(Counts!$AC$2:$AC$2903,Counts!$B$2:$B$2903,$C$3,Counts!$C$2:$C$2903,$C$4,Counts!$F$2:$F$2903,"Sep"),"") -> 0.12857143 | I17: =IFERROR(SUMIFS(Counts!$AD$2:$AD$2903,Counts!$B$2:$B$2903,$C$3,Counts!$C$2:$C$2903,$C$4)/SUMIFS(Counts!$AC$2:$AC$2903,Counts!$B$2:$B$2903,$C$3,Counts!$C$2:$C$2903,$C$4),"") -> 0.085798817
B18: HardHit% | C18: =IFERROR(SUMIFS(Counts!$AE$2:$AE$2903,Counts!$B$2:$B$2903,$C$3,Counts!$C$2:$C$2903,$C$4,Counts!$F$2:$F$2903,"Mar-Apr")/SUMIFS(Counts!$AC$2:$AC$2903,Counts!$B$2:$B$2903,$C$3,Counts!$C$2:$C$2903,$C$4,Counts!$F$2:$F$2903,"Mar-Apr"),"") -> 0.48484848 | D18: =IFERROR(SUMIFS(Counts!$AE$2:$AE$2903,Counts!$B$2:$B$2903,$C$3,Counts!$C$2:$C$2903,$C$4,Counts!$F$2:$F$2903,"May")/SUMIFS(Counts!$AC$2:$AC$2903,Counts!$B$2:$B$2903,$C$3,Counts!$C$2:$C$2903,$C$4,Counts!$F$2:$F$2903,"May"),"") -> 0.40540541 | E18: =IFERROR(SUMIFS(Counts!$AE$2:$AE$2903,Counts!$B$2:$B$2903,$C$3,Counts!$C$2:$C$2903,$C$4,Counts!$F$2:$F$2903,"Jun")/SUMIFS(Counts!$AC$2:$AC$2903,Counts!$B$2:$B$2903,$C$3,Counts!$C$2:$C$2903,$C$4,Counts!$F$2:$F$2903,"Jun"),"") -> 0.37209302 | F18: =IFERROR(SUMIFS(Counts!$AE$2:$AE$2903,Counts!$B$2:$B$2903,$C$3,Counts!$C$2:$C$2903,$C$4,Counts!$F$2:$F$2903,"Jul")/SUMIFS(Counts!$AC$2:$AC$2903,Counts!$B$2:$B$2903,$C$3,Counts!$C$2:$C$2903,$C$4,Counts!$F$2:$F$2903,"Jul"),"") -> 0.51020408 | G18: =IFERROR(SUMIFS(Counts!$AE$2:$AE$2903,Counts!$B$2:$B$2903,$C$3,Counts!$C$2:$C$2903,$C$4,Counts!$F$2:$F$2903,"Aug")/SUMIFS(Counts!$AC$2:$AC$2903,Counts!$B$2:$B$2903,$C$3,Counts!$C$2:$C$2903,$C$4,Counts!$F$2:$F$2903,"Aug"),"") -> 0.46575342 | H18: =IFERROR(SUMIFS(Counts!$AE$2:$AE$2903,Counts!$B$2:$B$2903,$C$3,Counts!$C$2:$C$2903,$C$4,Counts!$F$2:$F$2903,"Sep")/SUMIFS(Counts!$AC$2:$AC$2903,Counts!$B$2:$B$2903,$C$3,Counts!$C$2:$C$2903,$C$4,Counts!$F$2:$F$2903,"Sep"),"") -> 0.41428571 | I18: =IFERROR(SUMIFS(Counts!$AE$2:$AE$2903,Counts!$B$2:$B$2903,$C$3,Counts!$C$2:$C$2903,$C$4)/SUMIFS(Counts!$AC$2:$AC$2903,Counts!$B$2:$B$2903,$C$3,Counts!$C$2:$C$2903,$C$4),"") -> 0.44674556
B19: Avg EV | C19: =IFERROR(SUMIFS(Counts!$AG$2:$AG$2903,Counts!$B$2:$B$2903,$C$3,Counts!$C$2:$C$2903,$C$4,Counts!$F$2:$F$2903,"Mar-Apr")/SUMIFS(Counts!$AF$2:$AF$2903,Counts!$B$2:$B$2903,$C$3,Counts!$C$2:$C$2903,$C$4,Counts!$F$2:$F$2903,"Mar-Apr"),"") -> 89.504545 | D19: =IFERROR(SUMIFS(Counts!$AG$2:$AG$2903,Counts!$B$2:$B$2903,$C$3,Counts!$C$2:$C$2903,$C$4,Counts!$F$2:$F$2903,"May")/SUMIFS(Counts!$AF$2:$AF$2903,Counts!$B$2:$B$2903,$C$3,Counts!$C$2:$C$2903,$C$4,Counts!$F$2:$F$2903,"May"),"") -> 88.034286 | E19: =IFERROR(SUMIFS(Counts!$AG$2:$AG$2903,Counts!$B$2:$B$2903,$C$3,Counts!$C$2:$C$2903,$C$4,Counts!$F$2:$F$2903,"Jun")/SUMIFS(Counts!$AF$2:$AF$2903,Counts!$B$2:$B$2903,$C$3,Counts!$C$2:$C$2903,$C$4,Counts!$F$2:$F$2903,"Jun"),"") -> 86.388372 | F19: =IFERROR(SUMIFS(Counts!$AG$2:$AG$2903,Counts!$B$2:$B$2903,$C$3,Counts!$C$2:$C$2903,$C$4,Counts!$F$2:$F$2903,"Jul")/SUMIFS(Counts!$AF$2:$AF$2903,Counts!$B$2:$B$2903,$C$3,Counts!$C$2:$C$2903,$C$4,Counts!$F$2:$F$2903,"Jul"),"") -> 89.944898 | G19: =IFERROR(SUMIFS(Counts!$AG$2:$AG$2903,Counts!$B$2:$B$2903,$C$3,Counts!$C$2:$C$2903,$C$4,Counts!$F$2:$F$2903,"Aug")/SUMIFS(Counts!$AF$2:$AF$2903,Counts!$B$2:$B$2903,$C$3,Counts!$C$2:$C$2903,$C$4,Counts!$F$2:$F$2903,"Aug"),"") -> 90.10274 | H19: =IFERROR(SUMIFS(Counts!$AG$2:$AG$2903,Counts!$B$2:$B$2903,$C$3,Counts!$C$2:$C$2903,$C$4,Counts!$F$2:$F$2903,"Sep")/SUMIFS(Counts!$AF$2:$AF$2903,Counts!$B$2:$B$2903,$C$3,Counts!$C$2:$C$2903,$C$4,Counts!$F$2:$F$2903,"Sep"),"") -> 90.175714 | I19: =IFERROR(SUMIFS(Counts!$AG$2:$AG$2903,Counts!$B$2:$B$2903,$C$3,Counts!$C$2:$C$2903,$C$4)/SUMIFS(Counts!$AF$2:$AF$2903,Counts!$B$2:$B$2903,$C$3,Counts!$C$2:$C$2903,$C$4),"") -> 89.286607
B20: SweetSpot% | C20: =IFERROR(SUMIFS(Counts!$AH$2:$AH$2903,Counts!$B$2:$B$2903,$C$3,Counts!$C$2:$C$2903,$C$4,Counts!$F$2:$F$2903,"Mar-Apr")/SUMIFS(Counts!$AC$2:$AC$2903,Counts!$B$2:$B$2903,$C$3,Counts!$C$2:$C$2903,$C$4,Counts!$F$2:$F$2903,"Mar-Apr"),"") -> 0.27272727 | D20: =IFERROR(SUMIFS(Counts!$AH$2:$AH$2903,Counts!$B$2:$B$2903,$C$3,Counts!$C$2:$C$2903,$C$4,Counts!$F$2:$F$2903,"May")/SUMIFS(Counts!$AC$2:$AC$2903,Counts!$B$2:$B$2903,$C$3,Counts!$C$2:$C$2903,$C$4,Counts!$F$2:$F$2903,"May"),"") -> 0.37837838 | E20: =IFERROR(SUMIFS(Counts!$AH$2:$AH$2903,Counts!$B$2:$B$2903,$C$3,Counts!$C$2:$C$2903,$C$4,Counts!$F$2:$F$2903,"Jun")/SUMIFS(Counts!$AC$2:$AC$2903,Counts!$B$2:$B$2903,$C$3,Counts!$C$2:$C$2903,$C$4,Counts!$F$2:$F$2903,"Jun"),"") -> 0.44186047 | F20: =IFERROR(SUMIFS(Counts!$AH$2:$AH$2903,Counts!$B$2:$B$2903,$C$3,Counts!$C$2:$C$2903,$C$4,Counts!$F$2:$F$2903,"Jul")/SUMIFS(Counts!$AC$2:$AC$2903,Counts!$B$2:$B$2903,$C$3,Counts!$C$2:$C$2903,$C$4,Counts!$F$2:$F$2903,"Jul"),"") -> 0.32653061 | G20: =IFERROR(SUMIFS(Counts!$AH$2:$AH$2903,Counts!$B$2:$B$2903,$C$3,Counts!$C$2:$C$2903,$C$4,Counts!$F$2:$F$2903,"Aug")/SUMIFS(Counts!$AC$2:$AC$2903,Counts!$B$2:$B$2903,$C$3,Counts!$C$2:$C$2903,$C$4,Counts!$F$2:$F$2903,"Aug"),"") -> 0.32876712 | H20: =IFERROR(SUMIFS(Counts!$AH$2:$AH$2903,Counts!$B$2:$B$2903,$C$3,Counts!$C$2:$C$2903,$C$4,Counts!$F$2:$F$2903,"Sep")/SUMIFS(Counts!$AC$2:$AC$2903,Counts!$B$2:$B$2903,$C$3,Counts!$C$2:$C$2903,$C$4,Counts!$F$2:$F$2903,"Sep"),"") -> 0.28571429 | I20: =IFERROR(SUMIFS(Counts!$AH$2:$AH$2903,Counts!$B$2:$B$2903,$C$3,Counts!$C$2:$C$2903,$C$4)/SUMIFS(Counts!$AC$2:$AC$2903,Counts!$B$2:$B$2903,$C$3,Counts!$C$2:$C$2903,$C$4),"") -> 0.32840237
B21: Chase% | C21: =IFERROR(SUMIFS(Counts!$N$2:$N$2903,Counts!$B$2:$B$2903,$C$3,Counts!$C$2:$C$2903,$C$4,Counts!$F$2:$F$2903,"Mar-Apr")/SUMIFS(Counts!$M$2:$M$2903,Counts!$B$2:$B$2903,$C$3,Counts!$C$2:$C$2903,$C$4,Counts!$F$2:$F$2903,"Mar-Apr"),"") -> 0.26046512 | D21: =IFERROR(SUMIFS(Counts!$N$2:$N$2903,Counts!$B$2:$B$2903,$C$3,Counts!$C$2:$C$2903,$C$4,Counts!$F$2:$F$2903,"May")/SUMIFS(Counts!$M$2:$M$2903,Counts!$B$2:$B$2903,$C$3,Counts!$C$2:$C$2903,$C$4,Counts!$F$2:$F$2903,"May"),"") -> 0.19548872 | E21: =IFERROR(SUMIFS(Counts!$N$2:$N$2903,Counts!$B$2:$B$2903,$C$3,Counts!$C$2:$C$2903,$C$4,Counts!$F$2:$F$2903,"Jun")/SUMIFS(Counts!$M$2:$M$2903,Counts!$B$2:$B$2903,$C$3,Counts!$C$2:$C$2903,$C$4,Counts!$F$2:$F$2903,"Jun"),"") -> 0.27737226 | F21: =IFERROR(SUMIFS(Counts!$N$2:$N$2903,Counts!$B$2:$B$2903,$C$3,Counts!$C$2:$C$2903,$C$4,Counts!$F$2:$F$2903,"Jul")/SUMIFS(Counts!$M$2:$M$2903,Counts!$B$2:$B$2903,$C$3,Counts!$C$2:$C$2903,$C$4,Counts!$F$2:$F$2903,"Jul"),"") -> 0.22404372 | G21: =IFERROR(SUMIFS(Counts!$N$2:$N$2903,Counts!$B$2:$B$2903,$C$3,Counts!$C$2:$C$2903,$C$4,Counts!$F$2:$F$2903,"Aug")/SUMIFS(Counts!$M$2:$M$2903,Counts!$B$2:$B$2903,$C$3,Counts!$C$2:$C$2903,$C$4,Counts!$F$2:$F$2903,"Aug"),"") -> 0.25378788 | H21: =IFERROR(SUMIFS(Counts!$N$2:$N$2903,Counts!$B$2:$B$2903,$C$3,Counts!$C$2:$C$2903,$C$4,Counts!$F$2:$F$2903,"Sep")/SUMIFS(Counts!$M$2:$M$2903,Counts!$B$2:$B$2903,$C$3,Counts!$C$2:$C$2903,$C$4,Counts!$F$2:$F$2903,"Sep"),"") -> 0.25 | I21: =IFERROR(SUMIFS(Counts!$N$2:$N$2903,Counts!$B$2:$B$2903,$C$3,Counts!$C$2:$C$2903,$C$4)/SUMIFS(Counts!$M$2:$M$2903,Counts!$B$2:$B$2903,$C$3,Counts!$C$2:$C$2903,$C$4),"") -> 0.24568966
B22: Z-Swing% | C22: =IFERROR(SUMIFS(Counts!$K$2:$K$2903,Counts!$B$2:$B$2903,$C$3,Counts!$C$2:$C$2903,$C$4,Counts!$F$2:$F$2903,"Mar-Apr")/SUMIFS(Counts!$J$2:$J$2903,Counts!$B$2:$B$2903,$C$3,Counts!$C$2:$C$2903,$C$4,Counts!$F$2:$F$2903,"Mar-Apr"),"") -> 0.67788462 | D22: =IFERROR(SUMIFS(Counts!$K$2:$K$2903,Counts!$B$2:$B$2903,$C$3,Counts!$C$2:$C$2903,$C$4,Counts!$F$2:$F$2903,"May")/SUMIFS(Counts!$J$2:$J$2903,Counts!$B$2:$B$2903,$C$3,Counts!$C$2:$C$2903,$C$4,Counts!$F$2:$F$2903,"May"),"") -> 0.7 | E22: =IFERROR(SUMIFS(Counts!$K$2:$K$2903,Counts!$B$2:$B$2903,$C$3,Counts!$C$2:$C$2903,$C$4,Counts!$F$2:$F$2903,"Jun")/SUMIFS(Counts!$J$2:$J$2903,Counts!$B$2:$B$2903,$C$3,Counts!$C$2:$C$2903,$C$4,Counts!$F$2:$F$2903,"Jun"),"") -> 0.64 | F22: =IFERROR(SUMIFS(Counts!$K$2:$K$2903,Counts!$B$2:$B$2903,$C$3,Counts!$C$2:$C$2903,$C$4,Counts!$F$2:$F$2903,"Jul")/SUMIFS(Counts!$J$2:$J$2903,Counts!$B$2:$B$2903,$C$3,Counts!$C$2:$C$2903,$C$4,Counts!$F$2:$F$2903,"Jul"),"") -> 0.71084337 | G22: =IFERROR(SUMIFS(Counts!$K$2:$K$2903,Counts!$B$2:$B$2903,$C$3,Counts!$C$2:$C$2903,$C$4,Counts!$F$2:$F$2903,"Aug")/SUMIFS(Counts!$J$2:$J$2903,Counts!$B$2:$B$2903,$C$3,Counts!$C$2:$C$2903,$C$4,Counts!$F$2:$F$2903,"Aug"),"") -> 0.7239819 | H22: =IFERROR(SUMIFS(Counts!$K$2:$K$2903,Counts!$B$2:$B$2903,$C$3,Counts!$C$2:$C$2903,$C$4,Counts!$F$2:$F$2903,"Sep")/SUMIFS(Counts!$J$2:$J$2903,Counts!$B$2:$B$2903,$C$3,Counts!$C$2:$C$2903,$C$4,Counts!$F$2:$F$2903,"Sep"),"") -> 0.65333333 | I22: =IFERROR(SUMIFS(Counts!$K$2:$K$2903,Counts!$B$2:$B$2903,$C$3,Counts!$C$2:$C$2903,$C$4)/SUMIFS(Counts!$J$2:$J$2903,Counts!$B$2:$B$2903,$C$3,Counts!$C$2:$C$2903,$C$4),"") -> 0.68440367
B23: Whiff% | C23: =IFERROR(SUMIFS(Counts!$I$2:$I$2903,Counts!$B$2:$B$2903,$C$3,Counts!$C$2:$C$2903,$C$4,Counts!$F$2:$F$2903,"Mar-Apr")/SUMIFS(Counts!$H$2:$H$2903,Counts!$B$2:$B$2903,$C$3,Counts!$C$2:$C$2903,$C$4,Counts!$F$2:$F$2903,"Mar-Apr"),"") -> 0.25380711 | D23: =IFERROR(SUMIFS(Counts!$I$2:$I$2903,Counts!$B$2:$B$2903,$C$3,Counts!$C$2:$C$2903,$C$4,Counts!$F$2:$F$2903,"May")/SUMIFS(Counts!$H$2:$H$2903,Counts!$B$2:$B$2903,$C$3,Counts!$C$2:$C$2903,$C$4,Counts!$F$2:$F$2903,"May"),"") -> 0.25454545 | E23: =IFERROR(SUMIFS(Counts!$I$2:$I$2903,Counts!$B$2:$B$2903,$C$3,Counts!$C$2:$C$2903,$C$4,Counts!$F$2:$F$2903,"Jun")/SUMIFS(Counts!$H$2:$H$2903,Counts!$B$2:$B$2903,$C$3,Counts!$C$2:$C$2903,$C$4,Counts!$F$2:$F$2903,"Jun"),"") -> 0.29411765 | F23: =IFERROR(SUMIFS(Counts!$I$2:$I$2903,Counts!$B$2:$B$2903,$C$3,Counts!$C$2:$C$2903,$C$4,Counts!$F$2:$F$2903,"Jul")/SUMIFS(Counts!$H$2:$H$2903,Counts!$B$2:$B$2903,$C$3,Counts!$C$2:$C$2903,$C$4,Counts!$F$2:$F$2903,"Jul"),"") -> 0.18867925 | G23: =IFERROR(SUMIFS(Counts!$I$2:$I$2903,Counts!$B$2:$B$2903,$C$3,Counts!$C$2:$C$2903,$C$4,Counts!$F$2:$F$2903,"Aug")/SUMIFS(Counts!$H$2:$H$2903,Counts!$B$2:$B$2903,$C$3,Counts!$C$2:$C$2903,$C$4,Counts!$F$2:$F$2903,"Aug"),"") -> 0.2246696 | H23: =IFERROR(SUMIFS(Counts!$I$2:$I$2903,Counts!$B$2:$B$2903,$C$3,Counts!$C$2:$C$2903,$C$4,Counts!$F$2:$F$2903,"Sep")/SUMIFS(Counts!$H$2:$H$2903,Counts!$B$2:$B$2903,$C$3,Counts!$C$2:$C$2903,$C$4,Counts!$F$2:$F$2903,"Sep"),"") -> 0.20588235 | I23: =IFERROR(SUMIFS(Counts!$I$2:$I$2903,Counts!$B$2:$B$2903,$C$3,Counts!$C$2:$C$2903,$C$4)/SUMIFS(Counts!$H$2:$H$2903,Counts!$B$2:$B$2903,$C$3,Counts!$C$2:$C$2903,$C$4),"") -> 0.23330106
B24: Z-Contact% | C24: =IFERROR(1-SUMIFS(Counts!$L$2:$L$2903,Counts!$B$2:$B$2903,$C$3,Counts!$C$2:$C$2903,$C$4,Counts!$F$2:$F$2903,"Mar-Apr")/SUMIFS(Counts!$K$2:$K$2903,Counts!$B$2:$B$2903,$C$3,Counts!$C$2:$C$2903,$C$4,Counts!$F$2:$F$2903,"Mar-Apr"),"") -> 0.81560284 | D24: =IFERROR(1-SUMIFS(Counts!$L$2:$L$2903,Counts!$B$2:$B$2903,$C$3,Counts!$C$2:$C$2903,$C$4,Counts!$F$2:$F$2903,"May")/SUMIFS(Counts!$K$2:$K$2903,Counts!$B$2:$B$2903,$C$3,Counts!$C$2:$C$2903,$C$4,Counts!$F$2:$F$2903,"May"),"") -> 0.79761905 | E24: =IFERROR(1-SUMIFS(Counts!$L$2:$L$2903,Counts!$B$2:$B$2903,$C$3,Counts!$C$2:$C$2903,$C$4,Counts!$F$2:$F$2903,"Jun")/SUMIFS(Counts!$K$2:$K$2903,Counts!$B$2:$B$2903,$C$3,Counts!$C$2:$C$2903,$C$4,Counts!$F$2:$F$2903,"Jun"),"") -> 0.79166667 | F24: =IFERROR(1-SUMIFS(Counts!$L$2:$L$2903,Counts!$B$2:$B$2903,$C$3,Counts!$C$2:$C$2903,$C$4,Counts!$F$2:$F$2903,"Jul")/SUMIFS(Counts!$K$2:$K$2903,Counts!$B$2:$B$2903,$C$3,Counts!$C$2:$C$2903,$C$4,Counts!$F$2:$F$2903,"Jul"),"") -> 0.83898305 | G24: =IFERROR(1-SUMIFS(Counts!$L$2:$L$2903,Counts!$B$2:$B$2903,$C$3,Counts!$C$2:$C$2903,$C$4,Counts!$F$2:$F$2903,"Aug")/SUMIFS(Counts!$K$2:$K$2903,Counts!$B$2:$B$2903,$C$3,Counts!$C$2:$C$2903,$C$4,Counts!$F$2:$F$2903,"Aug"),"") -> 0.80625 | H24: =IFERROR(1-SUMIFS(Counts!$L$2:$L$2903,Counts!$B$2:$B$2903,$C$3,Counts!$C$2:$C$2903,$C$4,Counts!$F$2:$F$2903,"Sep")/SUMIFS(Counts!$K$2:$K$2903,Counts!$B$2:$B$2903,$C$3,Counts!$C$2:$C$2903,$C$4,Counts!$F$2:$F$2903,"Sep"),"") -> 0.88435374 | I24: =IFERROR(1-SUMIFS(Counts!$L$2:$L$2903,Counts!$B$2:$B$2903,$C$3,Counts!$C$2:$C$2903,$C$4)/SUMIFS(Counts!$K$2:$K$2903,Counts!$B$2:$B$2903,$C$3,Counts!$C$2:$C$2903,$C$4),"") -> 0.82573727
B25: Bat Speed | C25: =IFERROR(SUMIFS(Counts!$AJ$2:$AJ$2903,Counts!$B$2:$B$2903,$C$3,Counts!$C$2:$C$2903,$C$4,Counts!$F$2:$F$2903,"Mar-Apr")/SUMIFS(Counts!$AI$2:$AI$2903,Counts!$B$2:$B$2903,$C$3,Counts!$C$2:$C$2903,$C$4,Counts!$F$2:$F$2903,"Mar-Apr"),"") -> 73.5875 | D25: =IFERROR(SUMIFS(Counts!$AJ$2:$AJ$2903,Counts!$B$2:$B$2903,$C$3,Counts!$C$2:$C$2903,$C$4,Counts!$F$2:$F$2903,"May")/SUMIFS(Counts!$AI$2:$AI$2903,Counts!$B$2:$B$2903,$C$3,Counts!$C$2:$C$2903,$C$4,Counts!$F$2:$F$2903,"May"),"") -> 72.955319 | E25: =IFERROR(SUMIFS(Counts!$AJ$2:$AJ$2903,Counts!$B$2:$B$2903,$C$3,Counts!$C$2:$C$2903,$C$4,Counts!$F$2:$F$2903,"Jun")/SUMIFS(Counts!$AI$2:$AI$2903,Counts!$B$2:$B$2903,$C$3,Counts!$C$2:$C$2903,$C$4,Counts!$F$2:$F$2903,"Jun"),"") -> 74.679592 | F25: =IFERROR(SUMIFS(Counts!$AJ$2:$AJ$2903,Counts!$B$2:$B$2903,$C$3,Counts!$C$2:$C$2903,$C$4,Counts!$F$2:$F$2903,"Jul")/SUMIFS(Counts!$AI$2:$AI$2903,Counts!$B$2:$B$2903,$C$3,Counts!$C$2:$C$2903,$C$4,Counts!$F$2:$F$2903,"Jul"),"") -> 73.265217 | G25: =IFERROR(SUMIFS(Counts!$AJ$2:$AJ$2903,Counts!$B$2:$B$2903,$C$3,Counts!$C$2:$C$2903,$C$4,Counts!$F$2:$F$2903,"Aug")/SUMIFS(Counts!$AI$2:$AI$2903,Counts!$B$2:$B$2903,$C$3,Counts!$C$2:$C$2903,$C$4,Counts!$F$2:$F$2903,"Aug"),"") -> 73.643842 | H25: =IFERROR(SUMIFS(Counts!$AJ$2:$AJ$2903,Counts!$B$2:$B$2903,$C$3,Counts!$C$2:$C$2903,$C$4,Counts!$F$2:$F$2903,"Sep")/SUMIFS(Counts!$AI$2:$AI$2903,Counts!$B$2:$B$2903,$C$3,Counts!$C$2:$C$2903,$C$4,Counts!$F$2:$F$2903,"Sep"),"") -> 73.530556 | I25: =IFERROR(SUMIFS(Counts!$AJ$2:$AJ$2903,Counts!$B$2:$B$2903,$C$3,Counts!$C$2:$C$2903,$C$4)/SUMIFS(Counts!$AI$2:$AI$2903,Counts!$B$2:$B$2903,$C$3,Counts!$C$2:$C$2903,$C$4),"") -> 73.592351
B26: Fast-Swing% | C26: =IFERROR(SUMIFS(Counts!$AK$2:$AK$2903,Counts!$B$2:$B$2903,$C$3,Counts!$C$2:$C$2903,$C$4,Counts!$F$2:$F$2903,"Mar-Apr")/SUMIFS(Counts!$AI$2:$AI$2903,Counts!$B$2:$B$2903,$C$3,Counts!$C$2:$C$2903,$C$4,Counts!$F$2:$F$2903,"Mar-Apr"),"") -> 0.38068182 | D26: =IFERROR(SUMIFS(Counts!$AK$2:$AK$2903,Counts!$B$2:$B$2903,$C$3,Counts!$C$2:$C$2903,$C$4,Counts!$F$2:$F$2903,"May")/SUMIFS(Counts!$AI$2:$AI$2903,Counts!$B$2:$B$2903,$C$3,Counts!$C$2:$C$2903,$C$4,Counts!$F$2:$F$2903,"May"),"") -> 0.28723404 | E26: =IFERROR(SUMIFS(Counts!$AK$2:$AK$2903,Counts!$B$2:$B$2903,$C$3,Counts!$C$2:$C$2903,$C$4,Counts!$F$2:$F$2903,"Jun")/SUMIFS(Counts!$AI$2:$AI$2903,Counts!$B$2:$B$2903,$C$3,Counts!$C$2:$C$2903,$C$4,Counts!$F$2:$F$2903,"Jun"),"") -> 0.44897959 | F26: =IFERROR(SUMIFS(Counts!$AK$2:$AK$2903,Counts!$B$2:$B$2903,$C$3,Counts!$C$2:$C$2903,$C$4,Counts!$F$2:$F$2903,"Jul")/SUMIFS(Counts!$AI$2:$AI$2903,Counts!$B$2:$B$2903,$C$3,Counts!$C$2:$C$2903,$C$4,Counts!$F$2:$F$2903,"Jul"),"") -> 0.37681159 | G26: =IFERROR(SUMIFS(Counts!$AK$2:$AK$2903,Counts!$B$2:$B$2903,$C$3,Counts!$C$2:$C$2903,$C$4,Counts!$F$2:$F$2903,"Aug")/SUMIFS(Counts!$AI$2:$AI$2903,Counts!$B$2:$B$2903,$C$3,Counts!$C$2:$C$2903,$C$4,Counts!$F$2:$F$2903,"Aug"),"") -> 0.38916256 | H26: =IFERROR(SUMIFS(Counts!$AK$2:$AK$2903,Counts!$B$2:$B$2903,$C$3,Counts!$C$2:$C$2903,$C$4,Counts!$F$2:$F$2903,"Sep")/SUMIFS(Counts!$AI$2:$AI$2903,Counts!$B$2:$B$2903,$C$3,Counts!$C$2:$C$2903,$C$4,Counts!$F$2:$F$2903,"Sep"),"") -> 0.4 | I26: =IFERROR(SUMIFS(Counts!$AK$2:$AK$2903,Counts!$B$2:$B$2903,$C$3,Counts!$C$2:$C$2903,$C$4)/SUMIFS(Counts!$AI$2:$AI$2903,Counts!$B$2:$B$2903,$C$3,Counts!$C$2:$C$2903,$C$4),"") -> 0.38357705
B27: Run Value | C27: =IFERROR(SUMIFS(Counts!$O$2:$O$2903,Counts!$B$2:$B$2903,$C$3,Counts!$C$2:$C$2903,$C$4,Counts!$F$2:$F$2903,"Mar-Apr"),"") -> -6.731 | D27: =IFERROR(SUMIFS(Counts!$O$2:$O$2903,Counts!$B$2:$B$2903,$C$3,Counts!$C$2:$C$2903,$C$4,Counts!$F$2:$F$2903,"May"),"") -> -5.479 | E27: =IFERROR(SUMIFS(Counts!$O$2:$O$2903,Counts!$B$2:$B$2903,$C$3,Counts!$C$2:$C$2903,$C$4,Counts!$F$2:$F$2903,"Jun"),"") -> 1.445 | F27: =IFERROR(SUMIFS(Counts!$O$2:$O$2903,Counts!$B$2:$B$2903,$C$3,Counts!$C$2:$C$2903,$C$4,Counts!$F$2:$F$2903,"Jul"),"") -> -0.22 | G27: =IFERROR(SUMIFS(Counts!$O$2:$O$2903,Counts!$B$2:$B$2903,$C$3,Counts!$C$2:$C$2903,$C$4,Counts!$F$2:$F$2903,"Aug"),"") -> 10.436 | H27: =IFERROR(SUMIFS(Counts!$O$2:$O$2903,Counts!$B$2:$B$2903,$C$3,Counts!$C$2:$C$2903,$C$4,Counts!$F$2:$F$2903,"Sep"),"") -> 2.415 | I27: =IFERROR(SUMIFS(Counts!$O$2:$O$2903,Counts!$B$2:$B$2903,$C$3,Counts!$C$2:$C$2903,$C$4),"") -> 1.866
B29: Blank = no PA that month. Small monthly samples are noisy: read every rate with the PA row.

Sheet Team
B2: Team Offense by Month
B3: Team: | C3: ATH
B5: Metric | C5: Mar-Apr | D5: May | E5: Jun | F5: Jul | G5: Aug | H5: Sep | I5: Season | J5: MLB
B6: PA | C6: =IFERROR(SUMIFS(Counts!$P$2:$P$2903,Counts!$B$2:$B$2903,$C$3,Counts!$F$2:$F$2903,"Mar-Apr"),"") -> 1191 | D6: =IFERROR(SUMIFS(Counts!$P$2:$P$2903,Counts!$B$2:$B$2903,$C$3,Counts!$F$2:$F$2903,"May"),"") -> 1081 | E6: =IFERROR(SUMIFS(Counts!$P$2:$P$2903,Counts!$B$2:$B$2903,$C$3,Counts!$F$2:$F$2903,"Jun"),"") -> 1045 | F6: =IFERROR(SUMIFS(Counts!$P$2:$P$2903,Counts!$B$2:$B$2903,$C$3,Counts!$F$2:$F$2903,"Jul"),"") -> 884 | G6: =IFERROR(SUMIFS(Counts!$P$2:$P$2903,Counts!$B$2:$B$2903,$C$3,Counts!$F$2:$F$2903,"Aug"),"") -> 1034 | H6: =IFERROR(SUMIFS(Counts!$P$2:$P$2903,Counts!$B$2:$B$2903,$C$3,Counts!$F$2:$F$2903,"Sep"),"") -> 891 | I6: =IFERROR(SUMIFS(Counts!$P$2:$P$2903,Counts!$B$2:$B$2903,$C$3),"") -> 6126 | J6: =IFERROR(SUM(Counts!$P$2:$P$2903)/30,"") -> 6128.3
B7: AVG | C7: =IFERROR(SUMIFS(Counts!$R$2:$R$2903,Counts!$B$2:$B$2903,$C$3,Counts!$F$2:$F$2903,"Mar-Apr")/SUMIFS(Counts!$Q$2:$Q$2903,Counts!$B$2:$B$2903,$C$3,Counts!$F$2:$F$2903,"Mar-Apr"),"") -> 0.24596391 | D7: =IFERROR(SUMIFS(Counts!$R$2:$R$2903,Counts!$B$2:$B$2903,$C$3,Counts!$F$2:$F$2903,"May")/SUMIFS(Counts!$Q$2:$Q$2903,Counts!$B$2:$B$2903,$C$3,Counts!$F$2:$F$2903,"May"),"") -> 0.24894515 | E7: =IFERROR(SUMIFS(Counts!$R$2:$R$2903,Counts!$B$2:$B$2903,$C$3,Counts!$F$2:$F$2903,"Jun")/SUMIFS(Counts!$Q$2:$Q$2903,Counts!$B$2:$B$2903,$C$3,Counts!$F$2:$F$2903,"Jun"),"") -> 0.24679487 | F7: =IFERROR(SUMIFS(Counts!$R$2:$R$2903,Counts!$B$2:$B$2903,$C$3,Counts!$F$2:$F$2903,"Jul")/SUMIFS(Counts!$Q$2:$Q$2903,Counts!$B$2:$B$2903,$C$3,Counts!$F$2:$F$2903,"Jul"),"") -> 0.23279099 | G7: =IFERROR(SUMIFS(Counts!$R$2:$R$2903,Counts!$B$2:$B$2903,$C$3,Counts!$F$2:$F$2903,"Aug")/SUMIFS(Counts!$Q$2:$Q$2903,Counts!$B$2:$B$2903,$C$3,Counts!$F$2:$F$2903,"Aug"),"") -> 0.24867163 | H7: =IFERROR(SUMIFS(Counts!$R$2:$R$2903,Counts!$B$2:$B$2903,$C$3,Counts!$F$2:$F$2903,"Sep")/SUMIFS(Counts!$Q$2:$Q$2903,Counts!$B$2:$B$2903,$C$3,Counts!$F$2:$F$2903,"Sep"),"") -> 0.24537608 | I7: =IFERROR(SUMIFS(Counts!$R$2:$R$2903,Counts!$B$2:$B$2903,$C$3)/SUMIFS(Counts!$Q$2:$Q$2903,Counts!$B$2:$B$2903,$C$3),"") -> 0.24508017 | J7: =IFERROR(SUM(Counts!$R$2:$R$2903)/SUM(Counts!$Q$2:$Q$2903),"") -> 0.24397695
B8: OBP | C8: =IFERROR((SUMIFS(Counts!$R$2:$R$2903,Counts!$B$2:$B$2903,$C$3,Counts!$F$2:$F$2903,"Mar-Apr")+SUMIFS(Counts!$V$2:$V$2903,Counts!$B$2:$B$2903,$C$3,Counts!$F$2:$F$2903,"Mar-Apr")+SUMIFS(Counts!$W$2:$W$2903,Counts!$B$2:$B$2903,$C$3,Counts!$F$2:$F$2903,"Mar-Apr"))/(SUMIFS(Counts!$Q$2:$Q$2903,Counts!$B$2:$B$2903,$C$3,Counts!$F$2:$F$2903,"Mar-Apr")+SUMIFS(Counts!$V$2:$V$2903,Counts!$B$2:$B$2903,$C$3,Counts!$F$2:$F$2903,"Mar-Apr")+SUMIFS(Counts!$W$2:$W$2903,Counts!$B$2:$B$2903,$C$3,Counts!$F$2:$F$2903,"Mar-Apr")+SUMIFS(Counts!$X$2:$X$2903,Counts!$B$2:$B$2903,$C$3,Counts!$F$2:$F$2903,"Mar-Apr")),"") -> 0.32290786 | D8: =IFERROR((SUMIFS(Counts!$R$2:$R$2903,Counts!$B$2:$B$2903,$C$3,Counts!$F$2:$F$2903,"May")+SUMIFS(Counts!$V$2:$V$2903,Counts!$B$2:$B$2903,$C$3,Counts!$F$2:$F$2903,"May")+SUMIFS(Counts!$W$2:$W$2903,Counts!$B$2:$B$2903,$C$3,Counts!$F$2:$F$2903,"May"))/(SUMIFS(Counts!$Q$2:$Q$2903,Counts!$B$2:$B$2903,$C$3,Counts!$F$2:$F$2903,"May")+SUMIFS(Counts!$V$2:$V$2903,Counts!$B$2:$B$2903,$C$3,Counts!$F$2:$F$2903,"May")+SUMIFS(Counts!$W$2:$W$2903,Counts!$B$2:$B$2903,$C$3,Counts!$F$2:$F$2903,"May")+SUMIFS(Counts!$X$2:$X$2903,Counts!$B$2:$B$2903,$C$3,Counts!$F$2:$F$2903,"May")),"") -> 0.33580705 | E8: =IFERROR((SUMIFS(Counts!$R$2:$R$2903,Counts!$B$2:$B$2903,$C$3,Counts!$F$2:$F$2903,"Jun")+SUMIFS(Counts!$V$2:$V$2903,Counts!$B$2:$B$2903,$C$3,Counts!$F$2:$F$2903,"Jun")+SUMIFS(Counts!$W$2:$W$2903,Counts!$B$2:$B$2903,$C$3,Counts!$F$2:$F$2903,"Jun"))/(SUMIFS(Counts!$Q$2:$Q$2903,Counts!$B$2:$B$2903,$C$3,Counts!$F$2:$F$2903,"Jun")+SUMIFS(Counts!$V$2:$V$2903,Counts!$B$2:$B$2903,$C$3,Counts!$F$2:$F$2903,"Jun")+SUMIFS(Counts!$W$2:$W$2903,Counts!$B$2:$B$2903,$C$3,Counts!$F$2:$F$2903,"Jun")+SUMIFS(Counts!$X$2:$X$2903,Counts!$B$2:$B$2903,$C$3,Counts!$F$2:$F$2903,"Jun")),"") -> 0.32023011 | F8: =IFERROR((SUMIFS(Counts!$R$2:$R$2903,Counts!$B$2:$B$2903,$C$3,Counts!$F$2:$F$2903,"Jul")+SUMIFS(Counts!$V$2:$V$2903,Counts!$B$2:$B$2903,$C$3,Counts!$F$2:$F$2903,"Jul")+SUMIFS(Counts!$W$2:$W$2903,Counts!$B$2:$B$2903,$C$3,Counts!$F$2:$F$2903,"Jul"))/(SUMIFS(Counts!$Q$2:$Q$2903,Counts!$B$2:$B$2903,$C$3,Counts!$F$2:$F$2903,"Jul")+SUMIFS(Counts!$V$2:$V$2903,Counts!$B$2:$B$2903,$C$3,Counts!$F$2:$F$2903,"Jul")+SUMIFS(Counts!$W$2:$W$2903,Counts!$B$2:$B$2903,$C$3,Counts!$F$2:$F$2903,"Jul")+SUMIFS(Counts!$X$2:$X$2903,Counts!$B$2:$B$2903,$C$3,Counts!$F$2:$F$2903,"Jul")),"") -> 0.29579067 | G8: =IFERROR((SUMIFS(Counts!$R$2:$R$2903,Counts!$B$2:$B$2903,$C$3,Counts!$F$2:$F$2903,"Aug")+SUMIFS(Counts!$V$2:$V$2903,Counts!$B$2:$B$2903,$C$3,Counts!$F$2:$F$2903,"Aug")+SUMIFS(Counts!$W$2:$W$2903,Counts!$B$2:$B$2903,$C$3,Counts!$F$2:$F$2903,"Aug"))/(SUMIFS(Counts!$Q$2:$Q$2903,Counts!$B$2:$B$2903,$C$3,Counts!$F$2:$F$2903,"Aug")+SUMIFS(Counts!$V$2:$V$2903,Counts!$B$2:$B$2903,$C$3,Counts!$F$2:$F$2903,"Aug")+SUMIFS(Counts!$W$2:$W$2903,Counts!$B$2:$B$2903,$C$3,Counts!$F$2:$F$2903,"Aug")+SUMIFS(Counts!$X$2:$X$2903,Counts!$B$2:$B$2903,$C$3,Counts!$F$2:$F$2903,"Aug")),"") -> 0.31134821 | H8: =IFERROR((SUMIFS(Counts!$R$2:$R$2903,Counts!$B$2:$B$2903,$C$3,Counts!$F$2:$F$2903,"Sep")+SUMIFS(Counts!$V$2:$V$2903,Counts!$B$2:$B$2903,$C$3,Counts!$F$2:$F$2903,"Sep")+SUMIFS(Counts!$W$2:$W$2903,Counts!$B$2:$B$2903,$C$3,Counts!$F$2:$F$2903,"Sep"))/(SUMIFS(Counts!$Q$2:$Q$2903,Counts!$B$2:$B$2903,$C$3,Counts!$F$2:$F$2903,"Sep")+SUMIFS(Counts!$V$2:$V$2903,Counts!$B$2:$B$2903,$C$3,Counts!$F$2:$F$2903,"Sep")+SUMIFS(Counts!$W$2:$W$2903,Counts!$B$2:$B$2903,$C$3,Counts!$F$2:$F$2903,"Sep")+SUMIFS(Counts!$X$2:$X$2903,Counts!$B$2:$B$2903,$C$3,Counts!$F$2:$F$2903,"Sep")),"") -> 0.31046119 | I8: =IFERROR((SUMIFS(Counts!$R$2:$R$2903,Counts!$B$2:$B$2903,$C$3)+SUMIFS(Counts!$V$2:$V$2903,Counts!$B$2:$B$2903,$C$3)+SUMIFS(Counts!$W$2:$W$2903,Counts!$B$2:$B$2903,$C$3))/(SUMIFS(Counts!$Q$2:$Q$2903,Counts!$B$2:$B$2903,$C$3)+SUMIFS(Counts!$V$2:$V$2903,Counts!$B$2:$B$2903,$C$3)+SUMIFS(Counts!$W$2:$W$2903,Counts!$B$2:$B$2903,$C$3)+SUMIFS(Counts!$X$2:$X$2903,Counts!$B$2:$B$2903,$C$3)),"") -> 0.31705718 | J8: =IFERROR((SUM(Counts!$R$2:$R$2903)+SUM(Counts!$V$2:$V$2903)+SUM(Counts!$W$2:$W$2903))/(SUM(Counts!$Q$2:$Q$2903)+SUM(Counts!$V$2:$V$2903)+SUM(Counts!$W$2:$W$2903)+SUM(Counts!$X$2:$X$2903)),"") -> 0.31845492
B9: SLG | C9: =IFERROR((SUMIFS(Counts!$R$2:$R$2903,Counts!$B$2:$B$2903,$C$3,Counts!$F$2:$F$2903,"Mar-Apr")+SUMIFS(Counts!$S$2:$S$2903,Counts!$B$2:$B$2903,$C$3,Counts!$F$2:$F$2903,"Mar-Apr")+2*SUMIFS(Counts!$T$2:$T$2903,Counts!$B$2:$B$2903,$C$3,Counts!$F$2:$F$2903,"Mar-Apr")+3*SUMIFS(Counts!$U$2:$U$2903,Counts!$B$2:$B$2903,$C$3,Counts!$F$2:$F$2903,"Mar-Apr"))/SUMIFS(Counts!$Q$2:$Q$2903,Counts!$B$2:$B$2903,$C$3,Counts!$F$2:$F$2903,"Mar-Apr"),"") -> 0.39316239 | D9: =IFERROR((SUMIFS(Counts!$R$2:$R$2903,Counts!$B$2:$B$2903,$C$3,Counts!$F$2:$F$2903,"May")+SUMIFS(Counts!$S$2:$S$2903,Counts!$B$2:$B$2903,$C$3,Counts!$F$2:$F$2903,"May")+2*SUMIFS(Counts!$T$2:$T$2903,Counts!$B$2:$B$2903,$C$3,Counts!$F$2:$F$2903,"May")+3*SUMIFS(Counts!$U$2:$U$2903,Counts!$B$2:$B$2903,$C$3,Counts!$F$2:$F$2903,"May"))/SUMIFS(Counts!$Q$2:$Q$2903,Counts!$B$2:$B$2903,$C$3,Counts!$F$2:$F$2903,"May"),"") -> 0.39662447 | E9: =IFERROR((SUMIFS(Counts!$R$2:$R$2903,Counts!$B$2:$B$2903,$C$3,Counts!$F$2:$F$2903,"Jun")+SUMIFS(Counts!$S$2:$S$2903,Counts!$B$2:$B$2903,$C$3,Counts!$F$2:$F$2903,"Jun")+2*SUMIFS(Counts!$T$2:$T$2903,Counts!$B$2:$B$2903,$C$3,Counts!$F$2:$F$2903,"Jun")+3*SUMIFS(Counts!$U$2:$U$2903,Counts!$B$2:$B$2903,$C$3,Counts!$F$2:$F$2903,"Jun"))/SUMIFS(Counts!$Q$2:$Q$2903,Counts!$B$2:$B$2903,$C$3,Counts!$F$2:$F$2903,"Jun"),"") -> 0.43696581 | F9: =IFERROR((SUMIFS(Counts!$R$2:$R$2903,Counts!$B$2:$B$2903,$C$3,Counts!$F$2:$F$2903,"Jul")+SUMIFS(Counts!$S$2:$S$2903,Counts!$B$2:$B$2903,$C$3,Counts!$F$2:$F$2903,"Jul")+2*SUMIFS(Counts!$T$2:$T$2903,Counts!$B$2:$B$2903,$C$3,Counts!$F$2:$F$2903,"Jul")+3*SUMIFS(Counts!$U$2:$U$2903,Counts!$B$2:$B$2903,$C$3,Counts!$F$2:$F$2903,"Jul"))/SUMIFS(Counts!$Q$2:$Q$2903,Counts!$B$2:$B$2903,$C$3,Counts!$F$2:$F$2903,"Jul"),"") -> 0.37797247 | G9: =IFERROR((SUMIFS(Counts!$R$2:$R$2903,Counts!$B$2:$B$2903,$C$3,Counts!$F$2:$F$2903,"Aug")+SUMIFS(Counts!$S$2:$S$2903,Counts!$B$2:$B$2903,$C$3,Counts!$F$2:$F$2903,"Aug")+2*SUMIFS(Counts!$T$2:$T$2903,Counts!$B$2:$B$2903,$C$3,Counts!$F$2:$F$2903,"Aug")+3*SUMIFS(Counts!$U$2:$U$2903,Counts!$B$2:$B$2903,$C$3,Counts!$F$2:$F$2903,"Aug"))/SUMIFS(Counts!$Q$2:$Q$2903,Counts!$B$2:$B$2903,$C$3,Counts!$F$2:$F$2903,"Aug"),"") -> 0.38894793 | H9: =IFERROR((SUMIFS(Counts!$R$2:$R$2903,Counts!$B$2:$B$2903,$C$3,Counts!$F$2:$F$2903,"Sep")+SUMIFS(Counts!$S$2:$S$2903,Counts!$B$2:$B$2903,$C$3,Counts!$F$2:$F$2903,"Sep")+2*SUMIFS(Counts!$T$2:$T$2903,Counts!$B$2:$B$2903,$C$3,Counts!$F$2:$F$2903,"Sep")+3*SUMIFS(Counts!$U$2:$U$2903,Counts!$B$2:$B$2903,$C$3,Counts!$F$2:$F$2903,"Sep"))/SUMIFS(Counts!$Q$2:$Q$2903,Counts!$B$2:$B$2903,$C$3,Counts!$F$2:$F$2903,"Sep"),"") -> 0.41676942 | I9: =IFERROR((SUMIFS(Counts!$R$2:$R$2903,Counts!$B$2:$B$2903,$C$3)+SUMIFS(Counts!$S$2:$S$2903,Counts!$B$2:$B$2903,$C$3)+2*SUMIFS(Counts!$T$2:$T$2903,Counts!$B$2:$B$2903,$C$3)+3*SUMIFS(Counts!$U$2:$U$2903,Counts!$B$2:$B$2903,$C$3))/SUMIFS(Counts!$Q$2:$Q$2903,Counts!$B$2:$B$2903,$C$3),"") -> 0.40178571 | J9: =IFERROR((SUM(Counts!$R$2:$R$2903)+SUM(Counts!$S$2:$S$2903)+2*SUM(Counts!$T$2:$T$2903)+3*SUM(Counts!$U$2:$U$2903)/30)/SUM(Counts!$Q$2:$Q$2903),"") -> 0.30148288
B10: HR | C10: =IFERROR(SUMIFS(Counts!$U$2:$U$2903,Counts!$B$2:$B$2903,$C$3,Counts!$F$2:$F$2903,"Mar-Apr"),"") -> 32 | D10: =IFERROR(SUMIFS(Counts!$U$2:$U$2903,Counts!$B$2:$B$2903,$C$3,Counts!$F$2:$F$2903,"May"),"") -> 31 | E10: =IFERROR(SUMIFS(Counts!$U$2:$U$2903,Counts!$B$2:$B$2903,$C$3,Counts!$F$2:$F$2903,"Jun"),"") -> 46 | F10: =IFERROR(SUMIFS(Counts!$U$2:$U$2903,Counts!$B$2:$B$2903,$C$3,Counts!$F$2:$F$2903,"Jul"),"") -> 24 | G10: =IFERROR(SUMIFS(Counts!$U$2:$U$2903,Counts!$B$2:$B$2903,$C$3,Counts!$F$2:$F$2903,"Aug"),"") -> 27 | H10: =IFERROR(SUMIFS(Counts!$U$2:$U$2903,Counts!$B$2:$B$2903,$C$3,Counts!$F$2:$F$2903,"Sep"),"") -> 34 | I10: =IFERROR(SUMIFS(Counts!$U$2:$U$2903,Counts!$B$2:$B$2903,$C$3),"") -> 194 | J10: =IFERROR(SUM(Counts!$U$2:$U$2903)/30,"") -> 185.83333
B11: wOBA | C11: =IFERROR(SUMIFS(Counts!$Z$2:$Z$2903,Counts!$B$2:$B$2903,$C$3,Counts!$F$2:$F$2903,"Mar-Apr")/SUMIFS(Counts!$AA$2:$AA$2903,Counts!$B$2:$B$2903,$C$3,Counts!$F$2:$F$2903,"Mar-Apr"),"") -> 0.3145602 | D11: =IFERROR(SUMIFS(Counts!$Z$2:$Z$2903,Counts!$B$2:$B$2903,$C$3,Counts!$F$2:$F$2903,"May")/SUMIFS(Counts!$AA$2:$AA$2903,Counts!$B$2:$B$2903,$C$3,Counts!$F$2:$F$2903,"May"),"") -> 0.32516401 | E11: =IFERROR(SUMIFS(Counts!$Z$2:$Z$2903,Counts!$B$2:$B$2903,$C$3,Counts!$F$2:$F$2903,"Jun")/SUMIFS(Counts!$AA$2:$AA$2903,Counts!$B$2:$B$2903,$C$3,Counts!$F$2:$F$2903,"Jun"),"") -> 0.32993197 | F11: =IFERROR(SUMIFS(Counts!$Z$2:$Z$2903,Counts!$B$2:$B$2903,$C$3,Counts!$F$2:$F$2903,"Jul")/SUMIFS(Counts!$AA$2:$AA$2903,Counts!$B$2:$B$2903,$C$3,Counts!$F$2:$F$2903,"Jul"),"") -> 0.29726651 | G11: =IFERROR(SUMIFS(Counts!$Z$2:$Z$2903,Counts!$B$2:$B$2903,$C$3,Counts!$F$2:$F$2903,"Aug")/SUMIFS(Counts!$AA$2:$AA$2903,Counts!$B$2:$B$2903,$C$3,Counts!$F$2:$F$2903,"Aug"),"") -> 0.30967899 | H11: =IFERROR(SUMIFS(Counts!$Z$2:$Z$2903,Counts!$B$2:$B$2903,$C$3,Counts!$F$2:$F$2903,"Sep")/SUMIFS(Counts!$AA$2:$AA$2903,Counts!$B$2:$B$2903,$C$3,Counts!$F$2:$F$2903,"Sep"),"") -> 0.31944758 | I11: =IFERROR(SUMIFS(Counts!$Z$2:$Z$2903,Counts!$B$2:$B$2903,$C$3)/SUMIFS(Counts!$AA$2:$AA$2903,Counts!$B$2:$B$2903,$C$3),"") -> 0.31641914 | J11: =IFERROR(SUM(Counts!$Z$2:$Z$2903)/SUM(Counts!$AA$2:$AA$2903),"") -> 0.31645219
B12: xwOBA | C12: =IFERROR(SUMIFS(Counts!$AB$2:$AB$2903,Counts!$B$2:$B$2903,$C$3,Counts!$F$2:$F$2903,"Mar-Apr")/SUMIFS(Counts!$AA$2:$AA$2903,Counts!$B$2:$B$2903,$C$3,Counts!$F$2:$F$2903,"Mar-Apr"),"") -> 0.32566781 | D12: =IFERROR(SUMIFS(Counts!$AB$2:$AB$2903,Counts!$B$2:$B$2903,$C$3,Counts!$F$2:$F$2903,"May")/SUMIFS(Counts!$AA$2:$AA$2903,Counts!$B$2:$B$2903,$C$3,Counts!$F$2:$F$2903,"May"),"") -> 0.31621462 | E12: =IFERROR(SUMIFS(Counts!$AB$2:$AB$2903,Counts!$B$2:$B$2903,$C$3,Counts!$F$2:$F$2903,"Jun")/SUMIFS(Counts!$AA$2:$AA$2903,Counts!$B$2:$B$2903,$C$3,Counts!$F$2:$F$2903,"Jun"),"") -> 0.31129835 | F12: =IFERROR(SUMIFS(Counts!$AB$2:$AB$2903,Counts!$B$2:$B$2903,$C$3,Counts!$F$2:$F$2903,"Jul")/SUMIFS(Counts!$AA$2:$AA$2903,Counts!$B$2:$B$2903,$C$3,Counts!$F$2:$F$2903,"Jul"),"") -> 0.2955262 | G12: =IFERROR(SUMIFS(Counts!$AB$2:$AB$2903,Counts!$B$2:$B$2903,$C$3,Counts!$F$2:$F$2903,"Aug")/SUMIFS(Counts!$AA$2:$AA$2903,Counts!$B$2:$B$2903,$C$3,Counts!$F$2:$F$2903,"Aug"),"") -> 0.29818191 | H12: =IFERROR(SUMIFS(Counts!$AB$2:$AB$2903,Counts!$B$2:$B$2903,$C$3,Counts!$F$2:$F$2903,"Sep")/SUMIFS(Counts!$AA$2:$AA$2903,Counts!$B$2:$B$2903,$C$3,Counts!$F$2:$F$2903,"Sep"),"") -> 0.30332694 | I12: =IFERROR(SUMIFS(Counts!$AB$2:$AB$2903,Counts!$B$2:$B$2903,$C$3)/SUMIFS(Counts!$AA$2:$AA$2903,Counts!$B$2:$B$2903,$C$3),"") -> 0.3092637 | J12: =IFERROR(SUM(Counts!$AB$2:$AB$2903)/SUM(Counts!$AA$2:$AA$2903),"") -> 0.31454381
B13: xwOBA - wOBA | C13: =IFERROR((SUMIFS(Counts!$AB$2:$AB$2903,Counts!$B$2:$B$2903,$C$3,Counts!$F$2:$F$2903,"Mar-Apr")-SUMIFS(Counts!$Z$2:$Z$2903,Counts!$B$2:$B$2903,$C$3,Counts!$F$2:$F$2903,"Mar-Apr"))/SUMIFS(Counts!$AA$2:$AA$2903,Counts!$B$2:$B$2903,$C$3,Counts!$F$2:$F$2903,"Mar-Apr"),"") -> 0.0111076 | D13: =IFERROR((SUMIFS(Counts!$AB$2:$AB$2903,Counts!$B$2:$B$2903,$C$3,Counts!$F$2:$F$2903,"May")-SUMIFS(Counts!$Z$2:$Z$2903,Counts!$B$2:$B$2903,$C$3,Counts!$F$2:$F$2903,"May"))/SUMIFS(Counts!$AA$2:$AA$2903,Counts!$B$2:$B$2903,$C$3,Counts!$F$2:$F$2903,"May"),"") -> -0.0089493908 | E13: =IFERROR((SUMIFS(Counts!$AB$2:$AB$2903,Counts!$B$2:$B$2903,$C$3,Counts!$F$2:$F$2903,"Jun")-SUMIFS(Counts!$Z$2:$Z$2903,Counts!$B$2:$B$2903,$C$3,Counts!$F$2:$F$2903,"Jun"))/SUMIFS(Counts!$AA$2:$AA$2903,Counts!$B$2:$B$2903,$C$3,Counts!$F$2:$F$2903,"Jun"),"") -> -0.018633625 | F13: =IFERROR((SUMIFS(Counts!$AB$2:$AB$2903,Counts!$B$2:$B$2903,$C$3,Counts!$F$2:$F$2903,"Jul")-SUMIFS(Counts!$Z$2:$Z$2903,Counts!$B$2:$B$2903,$C$3,Counts!$F$2:$F$2903,"Jul"))/SUMIFS(Counts!$AA$2:$AA$2903,Counts!$B$2:$B$2903,$C$3,Counts!$F$2:$F$2903,"Jul"),"") -> -0.0017403189 | G13: =IFERROR((SUMIFS(Counts!$AB$2:$AB$2903,Counts!$B$2:$B$2903,$C$3,Counts!$F$2:$F$2903,"Aug")-SUMIFS(Counts!$Z$2:$Z$2903,Counts!$B$2:$B$2903,$C$3,Counts!$F$2:$F$2903,"Aug"))/SUMIFS(Counts!$AA$2:$AA$2903,Counts!$B$2:$B$2903,$C$3,Counts!$F$2:$F$2903,"Aug"),"") -> -0.011497082 | H13: =IFERROR((SUMIFS(Counts!$AB$2:$AB$2903,Counts!$B$2:$B$2903,$C$3,Counts!$F$2:$F$2903,"Sep")-SUMIFS(Counts!$Z$2:$Z$2903,Counts!$B$2:$B$2903,$C$3,Counts!$F$2:$F$2903,"Sep"))/SUMIFS(Counts!$AA$2:$AA$2903,Counts!$B$2:$B$2903,$C$3,Counts!$F$2:$F$2903,"Sep"),"") -> -0.016120631 | I13: =IFERROR((SUMIFS(Counts!$AB$2:$AB$2903,Counts!$B$2:$B$2903,$C$3)-SUMIFS(Counts!$Z$2:$Z$2903,Counts!$B$2:$B$2903,$C$3))/SUMIFS(Counts!$AA$2:$AA$2903,Counts!$B$2:$B$2903,$C$3),"") -> -0.0071554455 | J13: =IFERROR((SUM(Counts!$AB$2:$AB$2903)-SUM(Counts!$Z$2:$Z$2903))/SUM(Counts!$AA$2:$AA$2903),"") -> -0.0019083801
B14: K% | C14: =IFERROR(SUMIFS(Counts!$Y$2:$Y$2903,Counts!$B$2:$B$2903,$C$3,Counts!$F$2:$F$2903,"Mar-Apr")/SUMIFS(Counts!$P$2:$P$2903,Counts!$B$2:$B$2903,$C$3,Counts!$F$2:$F$2903,"Mar-Apr"),"") -> 0.22921914 | D14: =IFERROR(SUMIFS(Counts!$Y$2:$Y$2903,Counts!$B$2:$B$2903,$C$3,Counts!$F$2:$F$2903,"May")/SUMIFS(Counts!$P$2:$P$2903,Counts!$B$2:$B$2903,$C$3,Counts!$F$2:$F$2903,"May"),"") -> 0.21091582 | E14: =IFERROR(SUMIFS(Counts!$Y$2:$Y$2903,Counts!$B$2:$B$2903,$C$3,Counts!$F$2:$F$2903,"Jun")/SUMIFS(Counts!$P$2:$P$2903,Counts!$B$2:$B$2903,$C$3,Counts!$F$2:$F$2903,"Jun"),"") -> 0.23732057 | F14: =IFERROR(SUMIFS(Counts!$Y$2:$Y$2903,Counts!$B$2:$B$2903,$C$3,Counts!$F$2:$F$2903,"Jul")/SUMIFS(Counts!$P$2:$P$2903,Counts!$B$2:$B$2903,$C$3,Counts!$F$2:$F$2903,"Jul"),"") -> 0.2341629 | G14: =IFERROR(SUMIFS(Counts!$Y$2:$Y$2903,Counts!$B$2:$B$2903,$C$3,Counts!$F$2:$F$2903,"Aug")/SUMIFS(Counts!$P$2:$P$2903,Counts!$B$2:$B$2903,$C$3,Counts!$F$2:$F$2903,"Aug"),"") -> 0.21663443 | H14: =IFERROR(SUMIFS(Counts!$Y$2:$Y$2903,Counts!$B$2:$B$2903,$C$3,Counts!$F$2:$F$2903,"Sep")/SUMIFS(Counts!$P$2:$P$2903,Counts!$B$2:$B$2903,$C$3,Counts!$F$2:$F$2903,"Sep"),"") -> 0.21661055 | I14: =IFERROR(SUMIFS(Counts!$Y$2:$Y$2903,Counts!$B$2:$B$2903,$C$3)/SUMIFS(Counts!$P$2:$P$2903,Counts!$B$2:$B$2903,$C$3),"") -> 0.22412667 | J14: =IFERROR(SUM(Counts!$Y$2:$Y$2903)/SUM(Counts!$P$2:$P$2903)/30,"") -> 0.0073792442
